File: examples/squid/data/Gap_CSH_-61.6mg_m(T,5kOe,FC)_300K_to_4K_07062019.rso.dat
[Header]
TITLE,MPMS RSO Measurement
BYAPP,MPMS Measurement,1.1,Summary
FILEOPENTIME, 1559942107.309000 6/7/2019, 11:15:07 PM

INFO, APPNAME, MPMS MultiVu Application, Revision 1.61,  Build 082

INFO, NAME, H1257_HipII1-10_43.3mg+b20.7mg
INFO, WEIGHT, 64.000
INFO, AREA, 20.000
INFO, LENGTH, 0.000
INFO, SHAPE, 0
INFO, COMMENT, Hip II 110
INFO, SEQUENCE FILE: FC_5kOe_300_to_4_sweep.seq


INFO, BACKGROUND DATA FILE:, None


STARTUPAXIS,X,4,LINEAR,AUTO,0.000000,0.000000
STARTUPAXIS,Y1,5,LINEAR,AUTO,0.000000,0.000000


STARTUPGROUP,Longitudinal
FIELDGROUP,Longitudinal,1,2,3,4,5,6,7,8,9,10,11,19,20,21,22,23,35
FIELDGROUP,Transverse,1,2,3,4,12,13,14,15,16,17,18,24,25,26,27,28,35

PLOT_APPEARANCE,ALL,HORZ_GRID_ON,VERT_GRID_ON,MARKERS_AND_LINES

[Data]
Time,Comment,Field (Oe),Temperature (K),Long Moment (emu),Long Scan Std Dev,Long Offset (cm),Long Offset Std Dev,Long Algorithm,Long Reg Fit,Long Reg Factor,Trans Moment (emu),Trans Scan Std Dev,Trans Offset (cm),Trans Offset Std Dev,Trans Algorithm,Trans Reg Fit,Trans Reg Factor,Long Moment [w/o ABS] (emu),Long Scan Std Dev [w/o ABS],Long Offset [w/o ABS] (cm),Long Offset Std Dev [w/o ABS],Long Reg Fit [w/o ABS],Trans Moment [w/o ABS] (emu),Trans Scan Std Dev [w/o ABS],Trans Offset [w/o ABS] (cm),Trans Offset Std Dev [w/o ABS],Trans Reg Fit [w/o ABS],RSO Position (deg),Amplitude (cm),Frequency,Cycles to Average,Scans per Measurement,Delta Temp (K),Error,EC Comp. Running,Using ABS,
1559942107.309,,5.000000e+003,3.000184e+002,8.730614e-005,3.212180e-007,0.000000e+000,0.000000e+000,2,9.387726e-001,1.825000e+000,,,,,,,,,,,,,,,,,,0,4.000000e+000,1.000000e+000,3,8,2.258301e-002,0,,0,
1559942252.820,,5.000000e+003,2.966164e+002,8.697041e-005,2.731153e-007,0.000000e+000,0.000000e+000,2,9.373754e-001,1.825000e+000,,,,,,,,,,,,,,,,,,0,4.000000e+000,1.000000e+000,3,8,2.858887e+000,0,,0,
1559942317.250,,5.000000e+003,2.928543e+002,8.703141e-005,2.012624e-007,0.000000e+000,0.000000e+000,2,9.377870e-001,1.825000e+000,,,,,,,,,,,,,,,,,,0,4.000000e+000,1.000000e+000,3,8,3.992706e+000,0,,0,
1559942380.230,,5.000000e+003,2.889568e+002,8.682255e-005,3.333382e-007,0.000000e+000,0.000000e+000,2,9.368321e-001,1.825000e+000,,,,,,,,,,,,,,,,,,0,4.000000e+000,1.000000e+000,3,8,3.323700e+000,0,,0,
1559942444.400,,5.000000e+003,2.859717e+002,8.708744e-005,4.878863e-007,0.000000e+000,0.000000e+000,2,9.375239e-001,1.825000e+000,,,,,,,,,,,,,,,,,,0,4.000000e+000,1.000000e+000,3,8,2.263580e+000,0,,0,
1559942508.030,,5.000000e+003,2.841158e+002,8.725599e-005,1.786880e-007,0.000000e+000,0.000000e+000,2,9.375294e-001,1.825000e+000,,,,,,,,,,,,,,,,,,0,4.000000e+000,1.000000e+000,3,8,1.337799e+000,0,,0,
1559942570.130,,5.000000e+003,2.830080e+002,8.719241e-005,2.981583e-007,0.000000e+000,0.000000e+000,2,9.370866e-001,1.825000e+000,,,,,,,,,,,,,,,,,,0,4.000000e+000,1.000000e+000,3,8,9.872131e-001,0,,0,
1559942633.100,,5.000000e+003,2.818669e+002,8.721661e-005,2.903311e-007,0.000000e+000,0.000000e+000,2,9.377823e-001,1.825000e+000,,,,,,,,,,,,,,,,,,0,4.000000e+000,1.000000e+000,3,8,1.314728e+000,0,,0,
1559942695.200,,5.000000e+003,2.802615e+002,8.713273e-005,2.665619e-007,0.000000e+000,0.000000e+000,2,9.379188e-001,1.825000e+000,,,,,,,,,,,,,,,,,,0,4.000000e+000,1.000000e+000,3,8,1.826691e+000,0,,0,
1559942757.870,,5.000000e+003,2.782639e+002,8.710184e-005,2.919498e-007,0.000000e+000,0.000000e+000,2,9.377620e-001,1.825000e+000,,,,,,,,,,,,,,,,,,0,4.000000e+000,1.000000e+000,3,8,1.954102e+000,0,,0,
1559942820.040,,5.000000e+003,2.762209e+002,8.717272e-005,2.742064e-007,0.000000e+000,0.000000e+000,2,9.355682e-001,1.825000e+000,,,,,,,,,,,,,,,,,,0,4.000000e+000,1.000000e+000,3,8,1.962219e+000,0,,0,
1559942883.390,,5.000000e+003,2.741909e+002,8.746670e-005,3.947297e-007,0.000000e+000,0.000000e+000,2,9.378929e-001,1.825000e+000,,,,,,,,,,,,,,,,,,0,4.000000e+000,1.000000e+000,3,8,1.960297e+000,0,,0,
1559942946.271,,5.000000e+003,2.721724e+002,8.721247e-005,2.845291e-007,0.000000e+000,0.000000e+000,2,9.360512e-001,1.825000e+000,,,,,,,,,,,,,,,,,,0,4.000000e+000,1.000000e+000,3,8,1.966583e+000,0,,0,
1559943009.361,,5.000000e+003,2.701606e+002,8.728499e-005,3.476598e-007,0.000000e+000,0.000000e+000,2,9.400048e-001,1.825000e+000,,,,,,,,,,,,,,,,,,0,4.000000e+000,1.000000e+000,3,8,1.945709e+000,0,,0,
1559943072.521,,5.000000e+003,2.680923e+002,8.736498e-005,1.210719e-007,0.000000e+000,0.000000e+000,2,9.394735e-001,1.825000e+000,,,,,,,,,,,,,,,,,,0,4.000000e+000,1.000000e+000,3,8,1.940796e+000,0,,0,
1559943137.141,,5.000000e+003,2.660221e+002,8.719556e-005,2.633410e-007,0.000000e+000,0.000000e+000,2,9.367446e-001,1.825000e+000,,,,,,,,,,,,,,,,,,0,4.000000e+000,1.000000e+000,3,8,1.988312e+000,0,,0,
1559943200.541,,5.000000e+003,2.639460e+002,8.720742e-005,2.305700e-007,0.000000e+000,0.000000e+000,2,9.374300e-001,1.825000e+000,,,,,,,,,,,,,,,,,,0,4.000000e+000,1.000000e+000,3,8,1.878296e+000,0,,0,
1559943261.741,,5.000000e+003,2.620428e+002,8.723930e-005,2.161902e-007,0.000000e+000,0.000000e+000,2,9.372114e-001,1.825000e+000,,,,,,,,,,,,,,,,,,0,4.000000e+000,1.000000e+000,3,8,1.951599e+000,0,,0,
1559943324.631,,5.000000e+003,2.600366e+002,8.740145e-005,2.653042e-007,0.000000e+000,0.000000e+000,2,9.386526e-001,1.825000e+000,,,,,,,,,,,,,,,,,,0,4.000000e+000,1.000000e+000,3,8,1.972992e+000,0,,0,
1559943387.781,,5.000000e+003,2.580078e+002,8.732094e-005,2.749631e-007,0.000000e+000,0.000000e+000,2,9.380421e-001,1.825000e+000,,,,,,,,,,,,,,,,,,0,4.000000e+000,1.000000e+000,3,8,1.993195e+000,0,,0,
1559943451.261,,5.000000e+003,2.559888e+002,8.733089e-005,2.633910e-007,0.000000e+000,0.000000e+000,2,9.382513e-001,1.825000e+000,,,,,,,,,,,,,,,,,,0,4.000000e+000,1.000000e+000,3,8,1.955109e+000,0,,0,
1559943514.641,,5.000000e+003,2.539806e+002,8.742243e-005,3.671025e-007,0.000000e+000,0.000000e+000,2,9.370945e-001,1.825000e+000,,,,,,,,,,,,,,,,,,0,4.000000e+000,1.000000e+000,3,8,1.910004e+000,0,,0,
1559943576.551,,5.000000e+003,2.520093e+002,8.736951e-005,4.884334e-007,0.000000e+000,0.000000e+000,2,9.391246e-001,1.825000e+000,,,,,,,,,,,,,,,,,,0,4.000000e+000,1.000000e+000,3,8,1.944305e+000,0,,0,
1559943639.962,,5.000000e+003,2.499830e+002,8.750375e-005,2.513256e-007,0.000000e+000,0.000000e+000,2,9.382676e-001,1.825000e+000,,,,,,,,,,,,,,,,,,0,4.000000e+000,1.000000e+000,3,8,1.976105e+000,0,,0,
1559943702.902,,5.000000e+003,2.479105e+002,8.749750e-005,3.335421e-007,0.000000e+000,0.000000e+000,2,9.375906e-001,1.825000e+000,,,,,,,,,,,,,,,,,,0,4.000000e+000,1.000000e+000,3,8,1.998291e+000,0,,0,
1559943766.362,,5.000000e+003,2.458304e+002,8.733822e-005,1.810581e-007,0.000000e+000,0.000000e+000,2,9.378179e-001,1.825000e+000,,,,,,,,,,,,,,,,,,0,4.000000e+000,1.000000e+000,3,8,1.996307e+000,0,,0,
1559943830.512,,5.000000e+003,2.437246e+002,8.746979e-005,1.952831e-007,0.000000e+000,0.000000e+000,2,9.389297e-001,1.825000e+000,,,,,,,,,,,,,,,,,,0,4.000000e+000,1.000000e+000,3,8,2.015198e+000,0,,0,
1559943893.542,,5.000000e+003,2.416587e+002,8.744020e-005,4.119978e-007,0.000000e+000,0.000000e+000,2,9.384920e-001,1.825000e+000,,,,,,,,,,,,,,,,,,0,4.000000e+000,1.000000e+000,3,8,1.975204e+000,0,,0,
1559943955.872,,5.000000e+003,2.396226e+002,8.731290e-005,2.729015e-007,0.000000e+000,0.000000e+000,2,9.386631e-001,1.825000e+000,,,,,,,,,,,,,,,,,,0,4.000000e+000,1.000000e+000,3,8,1.929092e+000,0,,0,
1559944019.722,,5.000000e+003,2.375881e+002,8.742290e-005,3.238044e-007,0.000000e+000,0.000000e+000,2,9.386378e-001,1.825000e+000,,,,,,,,,,,,,,,,,,0,4.000000e+000,1.000000e+000,3,8,1.960709e+000,0,,0,
1559944083.382,,5.000000e+003,2.355253e+002,8.731478e-005,1.855642e-007,0.000000e+000,0.000000e+000,2,9.391583e-001,1.825000e+000,,,,,,,,,,,,,,,,,,0,4.000000e+000,1.000000e+000,3,8,1.969299e+000,0,,0,
1559944146.282,,5.000000e+003,2.334741e+002,8.737954e-005,2.541332e-007,0.000000e+000,0.000000e+000,2,9.391418e-001,1.825000e+000,,,,,,,,,,,,,,,,,,0,4.000000e+000,1.000000e+000,3,8,2.002594e+000,0,,0,
1559944211.432,,5.000000e+003,2.313716e+002,8.753022e-005,2.617878e-007,0.000000e+000,0.000000e+000,2,9.377323e-001,1.825000e+000,,,,,,,,,,,,,,,,,,0,4.000000e+000,1.000000e+000,3,8,2.023499e+000,0,,0,
1559944275.782,,5.000000e+003,2.292476e+002,8.753782e-005,4.791962e-007,0.000000e+000,0.000000e+000,2,9.388756e-001,1.825000e+000,,,,,,,,,,,,,,,,,,0,4.000000e+000,1.000000e+000,3,8,2.020691e+000,0,,0,
1559944338.752,,5.000000e+003,2.271571e+002,8.762992e-005,2.677477e-007,0.000000e+000,0.000000e+000,2,9.383133e-001,1.825000e+000,,,,,,,,,,,,,,,,,,0,4.000000e+000,1.000000e+000,3,8,1.992004e+000,0,,0,
1559944402.443,,5.000000e+003,2.250896e+002,8.770989e-005,3.264108e-007,0.000000e+000,0.000000e+000,2,9.392193e-001,1.825000e+000,,,,,,,,,,,,,,,,,,0,4.000000e+000,1.000000e+000,3,8,2.008087e+000,0,,0,
1559944465.663,,5.000000e+003,2.229881e+002,8.740874e-005,2.731417e-007,0.000000e+000,0.000000e+000,2,9.406319e-001,1.825000e+000,,,,,,,,,,,,,,,,,,0,4.000000e+000,1.000000e+000,3,8,1.972198e+000,0,,0,
1559944529.553,,5.000000e+003,2.209046e+002,8.751214e-005,2.869806e-007,0.000000e+000,0.000000e+000,2,9.383079e-001,1.825000e+000,,,,,,,,,,,,,,,,,,0,4.000000e+000,1.000000e+000,3,8,1.973694e+000,0,,0,
1559944592.263,,5.000000e+003,2.188439e+002,8.779333e-005,2.427845e-007,0.000000e+000,0.000000e+000,2,9.364138e-001,1.825000e+000,,,,,,,,,,,,,,,,,,0,4.000000e+000,1.000000e+000,3,8,1.950302e+000,0,,0,
1559944655.733,,5.000000e+003,2.168073e+002,8.756503e-005,3.547704e-007,0.000000e+000,0.000000e+000,2,9.380433e-001,1.825000e+000,,,,,,,,,,,,,,,,,,0,4.000000e+000,1.000000e+000,3,8,1.933594e+000,0,,0,
1559944719.183,,5.000000e+003,2.147854e+002,8.756137e-005,3.420178e-007,0.000000e+000,0.000000e+000,2,9.383696e-001,1.825000e+000,,,,,,,,,,,,,,,,,,0,4.000000e+000,1.000000e+000,3,8,1.927704e+000,0,,0,
1559944781.593,,5.000000e+003,2.128194e+002,8.754415e-005,3.264014e-007,0.000000e+000,0.000000e+000,2,9.391386e-001,1.825000e+000,,,,,,,,,,,,,,,,,,0,4.000000e+000,1.000000e+000,3,8,1.905792e+000,0,,0,
1559944845.233,,5.000000e+003,2.108345e+002,8.783861e-005,5.176127e-007,0.000000e+000,0.000000e+000,2,9.380527e-001,1.825000e+000,,,,,,,,,,,,,,,,,,0,4.000000e+000,1.000000e+000,3,8,1.916306e+000,0,,0,
1559944907.223,,5.000000e+003,2.089179e+002,8.769095e-005,2.942340e-007,0.000000e+000,0.000000e+000,2,9.385888e-001,1.825000e+000,,,,,,,,,,,,,,,,,,0,4.000000e+000,1.000000e+000,3,8,1.877106e+000,0,,0,
1559944970.163,,5.000000e+003,2.069620e+002,8.763133e-005,3.520069e-007,0.000000e+000,0.000000e+000,2,9.381674e-001,1.825000e+000,,,,,,,,,,,,,,,,,,0,4.000000e+000,1.000000e+000,3,8,1.886795e+000,0,,0,
1559945032.263,,5.000000e+003,2.049854e+002,8.769178e-005,2.997741e-007,0.000000e+000,0.000000e+000,2,9.384308e-001,1.825000e+000,,,,,,,,,,,,,,,,,,0,4.000000e+000,1.000000e+000,3,8,1.915894e+000,0,,0,
1559945094.244,,5.000000e+003,2.029767e+002,8.779405e-005,3.652960e-007,0.000000e+000,0.000000e+000,2,9.388361e-001,1.825000e+000,,,,,,,,,,,,,,,,,,0,4.000000e+000,1.000000e+000,3,8,2.025803e+000,0,,0,
1559945158.144,,5.000000e+003,2.008773e+002,8.768677e-005,1.782278e-007,0.000000e+000,0.000000e+000,2,9.386039e-001,1.825000e+000,,,,,,,,,,,,,,,,,,0,4.000000e+000,1.000000e+000,3,8,1.986603e+000,0,,0,
1559945221.844,,5.000000e+003,1.988029e+002,8.756817e-005,5.781485e-007,0.000000e+000,0.000000e+000,2,9.406573e-001,1.825000e+000,,,,,,,,,,,,,,,,,,0,4.000000e+000,1.000000e+000,3,8,1.972397e+000,0,,0,
1559945285.004,,5.000000e+003,1.967679e+002,8.782205e-005,3.188158e-007,0.000000e+000,0.000000e+000,2,9.380839e-001,1.825000e+000,,,,,,,,,,,,,,,,,,0,4.000000e+000,1.000000e+000,3,8,1.919693e+000,0,,0,
1559945348.854,,5.000000e+003,1.947527e+002,8.776541e-005,2.996313e-007,0.000000e+000,0.000000e+000,2,9.386704e-001,1.825000e+000,,,,,,,,,,,,,,,,,,0,4.000000e+000,1.000000e+000,3,8,1.935699e+000,0,,0,
1559945412.654,,5.000000e+003,1.927295e+002,8.786475e-005,4.141702e-007,0.000000e+000,0.000000e+000,2,9.401864e-001,1.825000e+000,,,,,,,,,,,,,,,,,,0,4.000000e+000,1.000000e+000,3,8,1.940292e+000,0,,0,
1559945474.754,,5.000000e+003,1.907765e+002,8.787322e-005,3.281940e-007,0.000000e+000,0.000000e+000,2,9.382602e-001,1.825000e+000,,,,,,,,,,,,,,,,,,0,4.000000e+000,1.000000e+000,3,8,1.921600e+000,0,,0,
1559945538.424,,5.000000e+003,1.887768e+002,8.792483e-005,3.260872e-007,0.000000e+000,0.000000e+000,2,9.392654e-001,1.825000e+000,,,,,,,,,,,,,,,,,,0,4.000000e+000,1.000000e+000,3,8,1.973801e+000,0,,0,
1559945602.374,,5.000000e+003,1.867055e+002,8.788141e-005,3.223973e-007,0.000000e+000,0.000000e+000,2,9.377910e-001,1.825000e+000,,,,,,,,,,,,,,,,,,0,4.000000e+000,1.000000e+000,3,8,1.986694e+000,0,,0,
1559945665.994,,5.000000e+003,1.846449e+002,8.804491e-005,3.536122e-007,0.000000e+000,0.000000e+000,2,9.383929e-001,1.825000e+000,,,,,,,,,,,,,,,,,,0,4.000000e+000,1.000000e+000,3,8,1.997696e+000,0,,0,
1559945729.644,,5.000000e+003,1.825569e+002,8.804683e-005,2.814808e-007,0.000000e+000,0.000000e+000,2,9.397768e-001,1.825000e+000,,,,,,,,,,,,,,,,,,0,4.000000e+000,1.000000e+000,3,8,1.993698e+000,0,,0,
1559945792.344,,5.000000e+003,1.804955e+002,8.788158e-005,3.379847e-007,0.000000e+000,0.000000e+000,2,9.391204e-001,1.825000e+000,,,,,,,,,,,,,,,,,,0,4.000000e+000,1.000000e+000,3,8,2.014313e+000,0,,0,
1559945855.825,,5.000000e+003,1.784351e+002,8.775426e-005,5.001513e-007,0.000000e+000,0.000000e+000,2,9.372236e-001,1.825000e+000,,,,,,,,,,,,,,,,,,0,4.000000e+000,1.000000e+000,3,8,2.004501e+000,0,,0,
1559945919.435,,5.000000e+003,1.763992e+002,8.799783e-005,2.119248e-007,0.000000e+000,0.000000e+000,2,9.363199e-001,1.825000e+000,,,,,,,,,,,,,,,,,,0,4.000000e+000,1.000000e+000,3,8,1.990707e+000,0,,0,
1559945983.135,,5.000000e+003,1.743635e+002,8.803840e-005,2.239156e-007,0.000000e+000,0.000000e+000,2,9.390285e-001,1.825000e+000,,,,,,,,,,,,,,,,,,0,4.000000e+000,1.000000e+000,3,8,1.948700e+000,0,,0,
1559946046.175,,5.000000e+003,1.723416e+002,8.792429e-005,2.412250e-007,0.000000e+000,0.000000e+000,2,9.373811e-001,1.825000e+000,,,,,,,,,,,,,,,,,,0,4.000000e+000,1.000000e+000,3,8,1.942093e+000,0,,0,
1559946109.265,,5.000000e+003,1.703552e+002,8.795920e-005,2.557634e-007,0.000000e+000,0.000000e+000,2,9.356342e-001,1.825000e+000,,,,,,,,,,,,,,,,,,0,4.000000e+000,1.000000e+000,3,8,1.904800e+000,0,,0,
1559946173.895,,5.000000e+003,1.683174e+002,8.816104e-005,3.541173e-007,0.000000e+000,0.000000e+000,2,9.393076e-001,1.825000e+000,,,,,,,,,,,,,,,,,,0,4.000000e+000,1.000000e+000,3,8,1.980209e+000,0,,0,
1559946237.955,,5.000000e+003,1.662495e+002,8.811124e-005,3.003919e-007,0.000000e+000,0.000000e+000,2,9.395268e-001,1.825000e+000,,,,,,,,,,,,,,,,,,0,4.000000e+000,1.000000e+000,3,8,2.022293e+000,0,,0,
1559946301.045,,5.000000e+003,1.641777e+002,8.823368e-005,3.858552e-007,0.000000e+000,0.000000e+000,2,9.393635e-001,1.825000e+000,,,,,,,,,,,,,,,,,,0,4.000000e+000,1.000000e+000,3,8,2.038696e+000,0,,0,
1559946364.085,,5.000000e+003,1.620903e+002,8.812336e-005,4.233027e-007,0.000000e+000,0.000000e+000,2,9.382464e-001,1.825000e+000,,,,,,,,,,,,,,,,,,0,4.000000e+000,1.000000e+000,3,8,2.027603e+000,0,,0,
1559946428.035,,5.000000e+003,1.600017e+002,8.817156e-005,2.108916e-007,0.000000e+000,0.000000e+000,2,9.393747e-001,1.825000e+000,,,,,,,,,,,,,,,,,,0,4.000000e+000,1.000000e+000,3,8,1.995697e+000,0,,0,
1559946491.025,,5.000000e+003,1.579127e+002,8.823814e-005,2.542959e-007,0.000000e+000,0.000000e+000,2,9.381590e-001,1.825000e+000,,,,,,,,,,,,,,,,,,0,4.000000e+000,1.000000e+000,3,8,1.990387e+000,0,,0,
1559946555.626,,5.000000e+003,1.558285e+002,8.827761e-005,1.487057e-007,0.000000e+000,0.000000e+000,2,9.382502e-001,1.825000e+000,,,,,,,,,,,,,,,,,,0,4.000000e+000,1.000000e+000,3,8,2.013000e+000,0,,0,
1559946619.776,,5.000000e+003,1.537659e+002,8.838162e-005,3.266283e-007,0.000000e+000,0.000000e+000,2,9.386036e-001,1.825000e+000,,,,,,,,,,,,,,,,,,0,4.000000e+000,1.000000e+000,3,8,1.968002e+000,0,,0,
1559946683.756,,5.000000e+003,1.517215e+002,8.817560e-005,3.424574e-007,0.000000e+000,0.000000e+000,2,9.382968e-001,1.825000e+000,,,,,,,,,,,,,,,,,,0,4.000000e+000,1.000000e+000,3,8,1.963394e+000,0,,0,
1559946746.736,,5.000000e+003,1.497050e+002,8.841501e-005,3.492386e-007,0.000000e+000,0.000000e+000,2,9.378873e-001,1.825000e+000,,,,,,,,,,,,,,,,,,0,4.000000e+000,1.000000e+000,3,8,1.942703e+000,0,,0,
1559946809.916,,5.000000e+003,1.476761e+002,8.850275e-005,3.819730e-007,0.000000e+000,0.000000e+000,2,9.378141e-001,1.825000e+000,,,,,,,,,,,,,,,,,,0,4.000000e+000,1.000000e+000,3,8,1.959000e+000,0,,0,
1559946874.516,,5.000000e+003,1.456184e+002,8.850514e-005,1.730257e-007,0.000000e+000,0.000000e+000,2,9.366692e-001,1.825000e+000,,,,,,,,,,,,,,,,,,0,4.000000e+000,1.000000e+000,3,8,2.022003e+000,0,,0,
1559946938.436,,5.000000e+003,1.435148e+002,8.832892e-005,3.049187e-007,0.000000e+000,0.000000e+000,2,9.373900e-001,1.825000e+000,,,,,,,,,,,,,,,,,,0,4.000000e+000,1.000000e+000,3,8,2.014099e+000,0,,0,
1559947001.456,,5.000000e+003,1.414532e+002,8.832827e-005,2.856751e-007,0.000000e+000,0.000000e+000,2,9.376320e-001,1.825000e+000,,,,,,,,,,,,,,,,,,0,4.000000e+000,1.000000e+000,3,8,1.983704e+000,0,,0,
1559947064.416,,5.000000e+003,1.393766e+002,8.831520e-005,3.735488e-007,0.000000e+000,0.000000e+000,2,9.371906e-001,1.825000e+000,,,,,,,,,,,,,,,,,,0,4.000000e+000,1.000000e+000,3,8,2.022705e+000,0,,0,
1559947127.586,,5.000000e+003,1.372796e+002,8.850188e-005,1.859149e-007,0.000000e+000,0.000000e+000,2,9.382288e-001,1.825000e+000,,,,,,,,,,,,,,,,,,0,4.000000e+000,1.000000e+000,3,8,1.993393e+000,0,,0,
1559947190.766,,5.000000e+003,1.352013e+002,8.834624e-005,3.951634e-007,0.000000e+000,0.000000e+000,2,9.389176e-001,1.825000e+000,,,,,,,,,,,,,,,,,,0,4.000000e+000,1.000000e+000,3,8,1.989304e+000,0,,0,
1559947254.587,,5.000000e+003,1.331326e+002,8.848056e-005,2.980263e-007,0.000000e+000,0.000000e+000,2,9.378644e-001,1.825000e+000,,,,,,,,,,,,,,,,,,0,4.000000e+000,1.000000e+000,3,8,1.983704e+000,0,,0,
1559947318.027,,5.000000e+003,1.310813e+002,8.847908e-005,5.218773e-007,0.000000e+000,0.000000e+000,2,9.366109e-001,1.825000e+000,,,,,,,,,,,,,,,,,,0,4.000000e+000,1.000000e+000,3,8,1.985199e+000,0,,0,
1559947381.477,,5.000000e+003,1.290322e+002,8.871995e-005,2.958222e-007,0.000000e+000,0.000000e+000,2,9.377934e-001,1.825000e+000,,,,,,,,,,,,,,,,,,0,4.000000e+000,1.000000e+000,3,8,1.962097e+000,0,,0,
1559947444.607,,5.000000e+003,1.269694e+002,8.847581e-005,3.387370e-007,0.000000e+000,0.000000e+000,2,9.369557e-001,1.825000e+000,,,,,,,,,,,,,,,,,,0,4.000000e+000,1.000000e+000,3,8,1.958900e+000,0,,0,
1559947509.257,,5.000000e+003,1.248674e+002,8.878564e-005,2.668513e-007,0.000000e+000,0.000000e+000,2,9.363417e-001,1.825000e+000,,,,,,,,,,,,,,,,,,0,4.000000e+000,1.000000e+000,3,8,2.054001e+000,0,,0,
1559947573.607,,5.000000e+003,1.227507e+002,8.873936e-005,2.741136e-007,0.000000e+000,0.000000e+000,2,9.376850e-001,1.825000e+000,,,,,,,,,,,,,,,,,,0,4.000000e+000,1.000000e+000,3,8,2.031700e+000,0,,0,
1559947637.277,,5.000000e+003,1.206467e+002,8.878736e-005,3.500754e-007,0.000000e+000,0.000000e+000,2,9.380320e-001,1.825000e+000,,,,,,,,,,,,,,,,,,0,4.000000e+000,1.000000e+000,3,8,2.020302e+000,0,,0,
1559947699.927,,5.000000e+003,1.185392e+002,8.869865e-005,1.999927e-007,0.000000e+000,0.000000e+000,2,9.360644e-001,1.825000e+000,,,,,,,,,,,,,,,,,,0,4.000000e+000,1.000000e+000,3,8,1.998199e+000,0,,0,
1559947762.647,,5.000000e+003,1.164765e+002,8.861716e-005,3.339059e-007,0.000000e+000,0.000000e+000,2,9.372266e-001,1.825000e+000,,,,,,,,,,,,,,,,,,0,4.000000e+000,1.000000e+000,3,8,2.040199e+000,0,,0,
1559947826.347,,5.000000e+003,1.143771e+002,8.878737e-005,1.935351e-007,0.000000e+000,0.000000e+000,2,9.377902e-001,1.825000e+000,,,,,,,,,,,,,,,,,,0,4.000000e+000,1.000000e+000,3,8,2.019905e+000,0,,0,
1559947890.257,,5.000000e+003,1.123093e+002,8.861953e-005,2.739288e-007,0.000000e+000,0.000000e+000,2,9.369675e-001,1.825000e+000,,,,,,,,,,,,,,,,,,0,4.000000e+000,1.000000e+000,3,8,1.950302e+000,0,,0,
1559947952.697,,5.000000e+003,1.102949e+002,8.877144e-005,1.560237e-007,0.000000e+000,0.000000e+000,2,9.386798e-001,1.825000e+000,,,,,,,,,,,,,,,,,,0,4.000000e+000,1.000000e+000,3,8,1.994003e+000,0,,0,
1559948016.178,,5.000000e+003,1.082534e+002,8.872036e-005,1.937996e-007,0.000000e+000,0.000000e+000,2,9.387013e-001,1.825000e+000,,,,,,,,,,,,,,,,,,0,4.000000e+000,1.000000e+000,3,8,1.942299e+000,0,,0,
1559948079.158,,5.000000e+003,1.061775e+002,8.875875e-005,2.672937e-007,0.000000e+000,0.000000e+000,2,9.386981e-001,1.825000e+000,,,,,,,,,,,,,,,,,,0,4.000000e+000,1.000000e+000,3,8,1.982597e+000,0,,0,
1559948143.308,,5.000000e+003,1.040460e+002,8.897108e-005,4.125430e-007,0.000000e+000,0.000000e+000,2,9.376844e-001,1.825000e+000,,,,,,,,,,,,,,,,,,0,4.000000e+000,1.000000e+000,3,8,2.031601e+000,0,,0,
1559948206.508,,5.000000e+003,1.019083e+002,8.897136e-005,2.557682e-007,0.000000e+000,0.000000e+000,2,9.373610e-001,1.825000e+000,,,,,,,,,,,,,,,,,,0,4.000000e+000,1.000000e+000,3,8,2.064995e+000,0,,0,
1559948269.438,,5.000000e+003,9.975350e+001,8.888524e-005,2.601008e-007,0.000000e+000,0.000000e+000,2,9.371164e-001,1.825000e+000,,,,,,,,,,,,,,,,,,0,4.000000e+000,1.000000e+000,3,8,2.072273e+000,0,,0,
1559948332.538,,5.000000e+003,9.760817e+001,8.887942e-005,2.260044e-007,0.000000e+000,0.000000e+000,2,9.378864e-001,1.825000e+000,,,,,,,,,,,,,,,,,,0,4.000000e+000,1.000000e+000,3,8,2.041672e+000,0,,0,
1559948396.508,,5.000000e+003,9.541915e+001,8.901465e-005,3.002259e-007,0.000000e+000,0.000000e+000,2,9.377224e-001,1.825000e+000,,,,,,,,,,,,,,,,,,0,4.000000e+000,1.000000e+000,3,8,2.075890e+000,0,,0,
1559948459.358,,5.000000e+003,9.326279e+001,8.909580e-005,2.771234e-007,0.000000e+000,0.000000e+000,2,9.375603e-001,1.825000e+000,,,,,,,,,,,,,,,,,,0,4.000000e+000,1.000000e+000,3,8,2.050285e+000,0,,0,
1559948523.258,,5.000000e+003,9.107291e+001,8.890308e-005,2.726468e-007,0.000000e+000,0.000000e+000,2,9.373552e-001,1.825000e+000,,,,,,,,,,,,,,,,,,0,4.000000e+000,1.000000e+000,3,8,2.013702e+000,0,,0,
1559948586.628,,5.000000e+003,8.891257e+001,8.904818e-005,3.071095e-007,0.000000e+000,0.000000e+000,2,9.383006e-001,1.825000e+000,,,,,,,,,,,,,,,,,,0,4.000000e+000,1.000000e+000,3,8,2.088989e+000,0,,0,
1559948649.568,,5.000000e+003,8.677507e+001,8.911983e-005,2.448241e-007,0.000000e+000,0.000000e+000,2,9.373562e-001,1.825000e+000,,,,,,,,,,,,,,,,,,0,4.000000e+000,1.000000e+000,3,8,2.035904e+000,0,,0,
1559948712.279,,5.000000e+003,8.463897e+001,8.925282e-005,2.763381e-007,0.000000e+000,0.000000e+000,2,9.379258e-001,1.825000e+000,,,,,,,,,,,,,,,,,,0,4.000000e+000,1.000000e+000,3,8,2.088303e+000,0,,0,
1559948775.429,,5.000000e+003,8.247832e+001,8.930844e-005,3.076914e-007,0.000000e+000,0.000000e+000,2,9.375756e-001,1.825000e+000,,,,,,,,,,,,,,,,,,0,4.000000e+000,1.000000e+000,3,8,2.069771e+000,0,,0,
1559948838.549,,5.000000e+003,8.031333e+001,8.925061e-005,1.774383e-007,0.000000e+000,0.000000e+000,2,9.376047e-001,1.825000e+000,,,,,,,,,,,,,,,,,,0,4.000000e+000,1.000000e+000,3,8,2.083809e+000,0,,0,
1559948900.689,,5.000000e+003,7.812509e+001,8.944570e-005,2.641448e-007,0.000000e+000,0.000000e+000,2,9.387085e-001,1.825000e+000,,,,,,,,,,,,,,,,,,0,4.000000e+000,1.000000e+000,3,8,2.138832e+000,0,,0,
1559948962.309,,5.000000e+003,7.594847e+001,8.925211e-005,2.177382e-007,0.000000e+000,0.000000e+000,2,9.376757e-001,1.825000e+000,,,,,,,,,,,,,,,,,,0,4.000000e+000,1.000000e+000,3,8,2.076714e+000,0,,0,
1559949025.749,,5.000000e+003,7.371077e+001,8.941100e-005,1.644255e-007,0.000000e+000,0.000000e+000,2,9.375944e-001,1.825000e+000,,,,,,,,,,,,,,,,,,0,4.000000e+000,1.000000e+000,3,8,2.148857e+000,0,,0,
1559949088.379,,5.000000e+003,7.148595e+001,8.940273e-005,2.584850e-007,0.000000e+000,0.000000e+000,2,9.379382e-001,1.825000e+000,,,,,,,,,,,,,,,,,,0,4.000000e+000,1.000000e+000,3,8,2.126839e+000,0,,0,
1559949151.119,,5.000000e+003,6.926880e+001,8.951755e-005,1.600242e-007,0.000000e+000,0.000000e+000,2,9.376805e-001,1.825000e+000,,,,,,,,,,,,,,,,,,0,4.000000e+000,1.000000e+000,3,8,2.088371e+000,0,,0,
1559949214.219,,5.000000e+003,6.702729e+001,8.953860e-005,1.704583e-007,0.000000e+000,0.000000e+000,2,9.378099e-001,1.825000e+000,,,,,,,,,,,,,,,,,,0,4.000000e+000,1.000000e+000,3,8,2.124527e+000,0,,0,
1559949276.849,,5.000000e+003,6.480794e+001,8.953951e-005,1.781591e-007,0.000000e+000,0.000000e+000,2,9.380456e-001,1.825000e+000,,,,,,,,,,,,,,,,,,0,4.000000e+000,1.000000e+000,3,8,2.129726e+000,0,,0,
1559949338.709,,5.000000e+003,6.257166e+001,8.962947e-005,2.237793e-007,0.000000e+000,0.000000e+000,2,9.374979e-001,1.825000e+000,,,,,,,,,,,,,,,,,,0,4.000000e+000,1.000000e+000,3,8,2.131889e+000,0,,0,
1559949402.149,,5.000000e+003,6.034904e+001,8.958912e-005,2.678012e-007,0.000000e+000,0.000000e+000,2,9.384147e-001,1.825000e+000,,,,,,,,,,,,,,,,,,0,4.000000e+000,1.000000e+000,3,8,2.132000e+000,0,,0,
1559949464.950,,5.000000e+003,5.804844e+001,8.978095e-005,2.723017e-007,0.000000e+000,0.000000e+000,2,9.369211e-001,1.825000e+000,,,,,,,,,,,,,,,,,,0,4.000000e+000,1.000000e+000,3,8,2.217670e+000,0,,0,
1559949527.560,,5.000000e+003,5.574203e+001,8.963802e-005,2.474887e-007,0.000000e+000,0.000000e+000,2,9.374549e-001,1.825000e+000,,,,,,,,,,,,,,,,,,0,4.000000e+000,1.000000e+000,3,8,2.295280e+000,0,,0,
1559949591.330,,5.000000e+003,5.337127e+001,8.981887e-005,1.639559e-007,0.000000e+000,0.000000e+000,2,9.371774e-001,1.825000e+000,,,,,,,,,,,,,,,,,,0,4.000000e+000,1.000000e+000,3,8,2.345657e+000,0,,0,
1559949653.340,,5.000000e+003,5.098341e+001,8.986763e-005,2.008311e-007,0.000000e+000,0.000000e+000,2,9.374147e-001,1.825000e+000,,,,,,,,,,,,,,,,,,0,4.000000e+000,1.000000e+000,3,8,2.285339e+000,0,,0,
1559949715.710,,5.000000e+003,4.862173e+001,8.993352e-005,1.123486e-007,0.000000e+000,0.000000e+000,2,9.372564e-001,1.825000e+000,,,,,,,,,,,,,,,,,,0,4.000000e+000,1.000000e+000,3,8,2.303032e+000,0,,0,
1559949778.460,,5.000000e+003,4.628444e+001,8.997063e-005,1.982905e-007,0.000000e+000,0.000000e+000,2,9.370180e-001,1.825000e+000,,,,,,,,,,,,,,,,,,0,4.000000e+000,1.000000e+000,3,8,2.233639e+000,0,,0,
1559949841.410,,5.000000e+003,4.396730e+001,9.006325e-005,1.369909e-007,0.000000e+000,0.000000e+000,2,9.373653e-001,1.825000e+000,,,,,,,,,,,,,,,,,,0,4.000000e+000,1.000000e+000,3,8,2.171650e+000,0,,0,
1559949902.340,,5.000000e+003,4.181010e+001,9.000243e-005,1.037138e-007,0.000000e+000,0.000000e+000,2,9.368088e-001,1.825000e+000,,,,,,,,,,,,,,,,,,0,4.000000e+000,1.000000e+000,3,8,2.051060e+000,0,,0,
1559949963.950,,5.000000e+003,3.963062e+001,9.012817e-005,1.933900e-007,0.000000e+000,0.000000e+000,2,9.376808e-001,1.825000e+000,,,,,,,,,,,,,,,,,,0,4.000000e+000,1.000000e+000,3,8,2.064720e+000,0,,0,
1559950025.870,,5.000000e+003,3.746131e+001,9.013503e-005,1.796178e-007,0.000000e+000,0.000000e+000,2,9.377164e-001,1.825000e+000,,,,,,,,,,,,,,,,,,0,4.000000e+000,1.000000e+000,3,8,2.069088e+000,0,,0,
1559950087.430,,5.000000e+003,3.528561e+001,9.013668e-005,9.759881e-008,0.000000e+000,0.000000e+000,2,9.380711e-001,1.825000e+000,,,,,,,,,,,,,,,,,,0,4.000000e+000,1.000000e+000,3,8,2.141510e+000,0,,0,
1559950149.600,,5.000000e+003,3.300738e+001,9.020544e-005,1.259125e-007,0.000000e+000,0.000000e+000,2,9.371272e-001,1.825000e+000,,,,,,,,,,,,,,,,,,0,4.000000e+000,1.000000e+000,3,8,2.150169e+000,0,,0,
1559950211.121,,5.000000e+003,3.078834e+001,9.030550e-005,9.898333e-008,0.000000e+000,0.000000e+000,2,9.370049e-001,1.825000e+000,,,,,,,,,,,,,,,,,,0,4.000000e+000,1.000000e+000,3,8,2.137430e+000,0,,0,
1559950273.351,,5.000000e+003,2.855481e+001,9.019886e-005,9.172571e-008,0.000000e+000,0.000000e+000,2,9.371918e-001,1.825000e+000,,,,,,,,,,,,,,,,,,0,4.000000e+000,1.000000e+000,3,8,2.165829e+000,0,,0,
1559950335.021,,5.000000e+003,2.633702e+001,9.028995e-005,7.164523e-008,0.000000e+000,0.000000e+000,2,9.373068e-001,1.825000e+000,,,,,,,,,,,,,,,,,,0,4.000000e+000,1.000000e+000,3,8,2.100950e+000,0,,0,
1559950397.441,,5.000000e+003,2.386477e+001,9.028250e-005,4.678400e-008,0.000000e+000,0.000000e+000,2,9.368601e-001,1.825000e+000,,,,,,,,,,,,,,,,,,0,4.000000e+000,1.000000e+000,3,8,2.163250e+000,0,,0,
1559950459.411,,5.000000e+003,2.199233e+001,9.033737e-005,5.901292e-008,0.000000e+000,0.000000e+000,2,9.376136e-001,1.825000e+000,,,,,,,,,,,,,,,,,,0,4.000000e+000,1.000000e+000,3,8,1.948000e+000,0,,0,
1559950521.661,,5.000000e+003,1.994623e+001,9.034064e-005,7.969174e-008,0.000000e+000,0.000000e+000,2,9.367953e-001,1.825000e+000,,,,,,,,,,,,,,,,,,0,4.000000e+000,1.000000e+000,3,8,1.929731e+000,0,,0,
1559950583.621,,5.000000e+003,1.789613e+001,9.030511e-005,5.392927e-008,0.000000e+000,0.000000e+000,2,9.370983e-001,1.825000e+000,,,,,,,,,,,,,,,,,,0,4.000000e+000,1.000000e+000,3,8,1.904861e+000,0,,0,
1559950646.341,,5.000000e+003,1.586662e+001,9.038136e-005,5.263338e-008,0.000000e+000,0.000000e+000,2,9.372817e-001,1.825000e+000,,,,,,,,,,,,,,,,,,0,4.000000e+000,1.000000e+000,3,8,1.993919e+000,0,,0,
1559950708.271,,5.000000e+003,1.372926e+001,9.037986e-005,3.787696e-008,0.000000e+000,0.000000e+000,2,9.370548e-001,1.825000e+000,,,,,,,,,,,,,,,,,,0,4.000000e+000,1.000000e+000,3,8,2.044559e+000,0,,0,
1559950770.121,,5.000000e+003,1.159555e+001,9.042181e-005,6.668112e-008,0.000000e+000,0.000000e+000,2,9.372696e-001,1.825000e+000,,,,,,,,,,,,,,,,,,0,4.000000e+000,1.000000e+000,3,8,2.071710e+000,0,,0,
1559950833.351,,5.000000e+003,9.469769e+000,9.040176e-005,3.395378e-008,0.000000e+000,0.000000e+000,2,9.371117e-001,1.825000e+000,,,,,,,,,,,,,,,,,,0,4.000000e+000,1.000000e+000,3,8,1.977176e+000,0,,0,
1559950897.022,,5.000000e+003,7.468857e+000,9.040149e-005,4.459669e-008,0.000000e+000,0.000000e+000,2,9.369171e-001,1.825000e+000,,,,,,,,,,,,,,,,,,0,4.000000e+000,1.000000e+000,3,8,1.659521e+000,0,,0,
1559950963.932,,5.000000e+003,5.548666e+000,9.038123e-005,1.881898e-008,0.000000e+000,0.000000e+000,2,9.372808e-001,1.825000e+000,,,,,,,,,,,,,,,,,,0,4.000000e+000,1.000000e+000,3,8,2.127459e+000,0,,0,
1559951156.612,,5.000000e+003,4.043010e+000,9.032938e-005,4.014739e-008,0.000000e+000,0.000000e+000,2,9.373116e-001,1.825000e+000,,,,,,,,,,,,,,,,,,0,4.000000e+000,1.000000e+000,3,8,4.046123e-001,0,,0,
1559951344.552,,5.000000e+003,3.985955e+000,9.030227e-005,2.881932e-008,0.000000e+000,0.000000e+000,2,9.372696e-001,1.825000e+000,,,,,,,,,,,,,,,,,,0,4.000000e+000,1.000000e+000,3,8,9.207821e-002,0,,0,
1559951406.192,,5.000000e+003,3.994924e+000,9.029808e-005,2.226735e-008,0.000000e+000,0.000000e+000,2,9.369177e-001,1.825000e+000,,,,,,,,,,,,,,,,,,0,4.000000e+000,1.000000e+000,3,8,1.108217e-002,0,,0,
1559951466.812,,5.000000e+003,3.997371e+000,9.027836e-005,1.288241e-008,0.000000e+000,0.000000e+000,2,9.369113e-001,1.825000e+000,,,,,,,,,,,,,,,,,,0,4.000000e+000,1.000000e+000,3,8,1.609397e-002,0,,0,
1559951527.702,,5.000000e+003,3.999717e+000,9.026682e-005,3.328599e-008,0.000000e+000,0.000000e+000,2,9.371307e-001,1.825000e+000,,,,,,,,,,,,,,,,,,0,4.000000e+000,1.000000e+000,3,8,9.001970e-003,0,,0,
1559951588.602,,5.000000e+003,4.001188e+000,9.026485e-005,1.875778e-008,0.000000e+000,0.000000e+000,2,9.369454e-001,1.825000e+000,,,,,,,,,,,,,,,,,,0,4.000000e+000,1.000000e+000,3,8,1.019192e-002,0,,0,
1559951649.703,,5.000000e+003,4.001881e+000,9.025470e-005,2.964535e-008,0.000000e+000,0.000000e+000,2,9.370291e-001,1.825000e+000,,,,,,,,,,,,,,,,,,0,4.000000e+000,1.000000e+000,3,8,3.924847e-003,0,,0,
1559951724.033,,5.000000e+003,4.004777e+000,9.025907e-005,1.633908e-008,0.000000e+000,0.000000e+000,2,9.369777e-001,1.825000e+000,,,,,,,,,,,,,,,,,,0,4.000000e+000,1.000000e+000,3,8,4.088879e-003,0,,0,
1559951784.293,,5.000000e+003,4.006907e+000,9.024779e-005,1.215414e-008,0.000000e+000,0.000000e+000,2,9.368256e-001,1.825000e+000,,,,,,,,,,,,,,,,,,0,4.000000e+000,1.000000e+000,3,8,1.259804e-003,0,,0,