File: examples/squid/data/H1258_CSH_HipII110_[L]_45,7mg_+b13,7mg_m(T,5kOe,FC)_300K_to_4K_12062019.rso.dat
[Header]
TITLE,MPMS RSO Measurement
BYAPP,MPMS Measurement,1.1,Summary
FILEOPENTIME, 1560334082.880000 6/12/2019, 12:08:02 PM

INFO, APPNAME, MPMS MultiVu Application, Revision 1.61,  Build 082

INFO, NAME, H1258_HipII110_[l]_45.7mg+b13.7mg
INFO, WEIGHT, 59.400
INFO, AREA, 20.000
INFO, LENGTH, 0.000
INFO, SHAPE, 0
INFO, COMMENT, Hip II 110
INFO, SEQUENCE FILE: FC_5kOe_300_to_4_sweep.seq


INFO, BACKGROUND DATA FILE:, None


STARTUPAXIS,X,4,LINEAR,AUTO,0.000000,0.000000
STARTUPAXIS,Y1,5,LINEAR,AUTO,0.000000,0.000000


STARTUPGROUP,Longitudinal
FIELDGROUP,Longitudinal,1,2,3,4,5,6,7,8,9,10,11,19,20,21,22,23,35
FIELDGROUP,Transverse,1,2,3,4,12,13,14,15,16,17,18,24,25,26,27,28,35

PLOT_APPEARANCE,ALL,HORZ_GRID_ON,VERT_GRID_ON,MARKERS_AND_LINES

[Data]
Time,Comment,Field (Oe),Temperature (K),Long Moment (emu),Long Scan Std Dev,Long Offset (cm),Long Offset Std Dev,Long Algorithm,Long Reg Fit,Long Reg Factor,Trans Moment (emu),Trans Scan Std Dev,Trans Offset (cm),Trans Offset Std Dev,Trans Algorithm,Trans Reg Fit,Trans Reg Factor,Long Moment [w/o ABS] (emu),Long Scan Std Dev [w/o ABS],Long Offset [w/o ABS] (cm),Long Offset Std Dev [w/o ABS],Long Reg Fit [w/o ABS],Trans Moment [w/o ABS] (emu),Trans Scan Std Dev [w/o ABS],Trans Offset [w/o ABS] (cm),Trans Offset Std Dev [w/o ABS],Trans Reg Fit [w/o ABS],RSO Position (deg),Amplitude (cm),Frequency,Cycles to Average,Scans per Measurement,Delta Temp (K),Error,EC Comp. Running,Using ABS,
1560334082.880,,5.000000e+003,2.999980e+002,1.110859e-005,3.430638e-007,0.000000e+000,0.000000e+000,2,6.551597e-001,1.825000e+000,,,,,,,,,,,,,,,,,,0,4.000000e+000,1.000000e+000,3,8,2.249146e-002,0,,0,
1560334255.741,,5.000000e+003,2.962074e+002,1.087071e-005,2.458327e-007,0.000000e+000,0.000000e+000,2,6.509444e-001,1.825000e+000,,,,,,,,,,,,,,,,,,0,4.000000e+000,1.000000e+000,3,8,3.757599e+000,0,,0,
1560334319.001,,5.000000e+003,2.918695e+002,1.121436e-005,3.045635e-007,0.000000e+000,0.000000e+000,2,6.668232e-001,1.825000e+000,,,,,,,,,,,,,,,,,,0,4.000000e+000,1.000000e+000,3,8,4.178314e+000,0,,0,
1560334382.661,,5.000000e+003,2.879207e+002,1.121537e-005,3.353877e-007,0.000000e+000,0.000000e+000,2,6.541163e-001,1.825000e+000,,,,,,,,,,,,,,,,,,0,4.000000e+000,1.000000e+000,3,8,3.370819e+000,0,,0,
1560334446.971,,5.000000e+003,2.850359e+002,1.137571e-005,2.232565e-007,0.000000e+000,0.000000e+000,2,6.735490e-001,1.825000e+000,,,,,,,,,,,,,,,,,,0,4.000000e+000,1.000000e+000,3,8,2.096405e+000,0,,0,
1560334511.221,,5.000000e+003,2.833881e+002,1.148678e-005,4.226590e-007,0.000000e+000,0.000000e+000,2,6.666607e-001,1.825000e+000,,,,,,,,,,,,,,,,,,0,4.000000e+000,1.000000e+000,3,8,1.090485e+000,0,,0,
1560334573.021,,5.000000e+003,2.825319e+002,1.155577e-005,2.439338e-007,0.000000e+000,0.000000e+000,2,6.759242e-001,1.825000e+000,,,,,,,,,,,,,,,,,,0,4.000000e+000,1.000000e+000,3,8,7.451172e-001,0,,0,
1560334635.621,,5.000000e+003,2.815397e+002,1.152263e-005,3.503170e-007,0.000000e+000,0.000000e+000,2,6.766173e-001,1.825000e+000,,,,,,,,,,,,,,,,,,0,4.000000e+000,1.000000e+000,3,8,1.291687e+000,0,,0,
1560334698.841,,5.000000e+003,2.798544e+002,1.146163e-005,3.200780e-007,0.000000e+000,0.000000e+000,2,6.595491e-001,1.825000e+000,,,,,,,,,,,,,,,,,,0,4.000000e+000,1.000000e+000,3,8,1.918610e+000,0,,0,
1560334760.691,,5.000000e+003,2.777591e+002,1.158179e-005,2.650177e-007,0.000000e+000,0.000000e+000,2,6.740347e-001,1.825000e+000,,,,,,,,,,,,,,,,,,0,4.000000e+000,1.000000e+000,3,8,2.119110e+000,0,,0,
1560334823.871,,5.000000e+003,2.755803e+002,1.168432e-005,1.880435e-007,0.000000e+000,0.000000e+000,2,6.855965e-001,1.825000e+000,,,,,,,,,,,,,,,,,,0,4.000000e+000,1.000000e+000,3,8,2.028107e+000,0,,0,
1560334886.271,,5.000000e+003,2.734847e+002,1.178861e-005,3.376831e-007,0.000000e+000,0.000000e+000,2,6.866969e-001,1.825000e+000,,,,,,,,,,,,,,,,,,0,4.000000e+000,1.000000e+000,3,8,1.968506e+000,0,,0,
1560334949.402,,5.000000e+003,2.714855e+002,1.162197e-005,4.246098e-007,0.000000e+000,0.000000e+000,2,6.654861e-001,1.825000e+000,,,,,,,,,,,,,,,,,,0,4.000000e+000,1.000000e+000,3,8,1.920074e+000,0,,0,
1560335012.332,,5.000000e+003,2.694972e+002,1.169223e-005,1.910394e-007,0.000000e+000,0.000000e+000,2,6.687562e-001,1.825000e+000,,,,,,,,,,,,,,,,,,0,4.000000e+000,1.000000e+000,3,8,1.944519e+000,0,,0,
1560335074.442,,5.000000e+003,2.675320e+002,1.168003e-005,2.456360e-007,0.000000e+000,0.000000e+000,2,6.733419e-001,1.825000e+000,,,,,,,,,,,,,,,,,,0,4.000000e+000,1.000000e+000,3,8,1.949890e+000,0,,0,
1560335137.422,,5.000000e+003,2.655472e+002,1.181958e-005,3.540235e-007,0.000000e+000,0.000000e+000,2,6.828414e-001,1.825000e+000,,,,,,,,,,,,,,,,,,0,4.000000e+000,1.000000e+000,3,8,1.928589e+000,0,,0,
1560335198.862,,5.000000e+003,2.636227e+002,1.201906e-005,3.041907e-007,0.000000e+000,0.000000e+000,2,6.785644e-001,1.825000e+000,,,,,,,,,,,,,,,,,,0,4.000000e+000,1.000000e+000,3,8,1.795624e+000,0,,0,
1560335262.222,,5.000000e+003,2.616826e+002,1.208639e-005,2.403044e-007,0.000000e+000,0.000000e+000,2,6.783162e-001,1.825000e+000,,,,,,,,,,,,,,,,,,0,4.000000e+000,1.000000e+000,3,8,1.920898e+000,0,,0,
1560335322.912,,5.000000e+003,2.597167e+002,1.199986e-005,2.379597e-007,0.000000e+000,0.000000e+000,2,6.935660e-001,1.825000e+000,,,,,,,,,,,,,,,,,,0,4.000000e+000,1.000000e+000,3,8,1.993500e+000,0,,0,
1560335385.832,,5.000000e+003,2.576671e+002,1.204904e-005,2.582787e-007,0.000000e+000,0.000000e+000,2,6.900403e-001,1.825000e+000,,,,,,,,,,,,,,,,,,0,4.000000e+000,1.000000e+000,3,8,2.021027e+000,0,,0,
1560335447.882,,5.000000e+003,2.556081e+002,1.238741e-005,2.410585e-007,0.000000e+000,0.000000e+000,2,6.941471e-001,1.825000e+000,,,,,,,,,,,,,,,,,,0,4.000000e+000,1.000000e+000,3,8,1.957611e+000,0,,0,
1560335509.952,,5.000000e+003,2.535702e+002,1.209218e-005,2.352087e-007,0.000000e+000,0.000000e+000,2,6.869419e-001,1.825000e+000,,,,,,,,,,,,,,,,,,0,4.000000e+000,1.000000e+000,3,8,1.903900e+000,0,,0,
1560335571.542,,5.000000e+003,2.515526e+002,1.245945e-005,1.290807e-007,0.000000e+000,0.000000e+000,2,6.924952e-001,1.825000e+000,,,,,,,,,,,,,,,,,,0,4.000000e+000,1.000000e+000,3,8,1.937302e+000,0,,0,
1560335633.632,,5.000000e+003,2.495685e+002,1.231202e-005,2.232178e-007,0.000000e+000,0.000000e+000,2,6.979929e-001,1.825000e+000,,,,,,,,,,,,,,,,,,0,4.000000e+000,1.000000e+000,3,8,1.916000e+000,0,,0,
1560335696.533,,5.000000e+003,2.475539e+002,1.239155e-005,4.130077e-007,0.000000e+000,0.000000e+000,2,6.945870e-001,1.825000e+000,,,,,,,,,,,,,,,,,,0,4.000000e+000,1.000000e+000,3,8,1.901398e+000,0,,0,
1560335758.233,,5.000000e+003,2.456059e+002,1.249903e-005,2.834013e-007,0.000000e+000,0.000000e+000,2,7.068683e-001,1.825000e+000,,,,,,,,,,,,,,,,,,0,4.000000e+000,1.000000e+000,3,8,1.917694e+000,0,,0,
1560335820.143,,5.000000e+003,2.436512e+002,1.242531e-005,2.870279e-007,0.000000e+000,0.000000e+000,2,6.946532e-001,1.825000e+000,,,,,,,,,,,,,,,,,,0,4.000000e+000,1.000000e+000,3,8,1.910706e+000,0,,0,
1560335882.313,,5.000000e+003,2.416681e+002,1.251847e-005,4.060527e-007,0.000000e+000,0.000000e+000,2,6.974141e-001,1.825000e+000,,,,,,,,,,,,,,,,,,0,4.000000e+000,1.000000e+000,3,8,1.946091e+000,0,,0,
1560335944.843,,5.000000e+003,2.396341e+002,1.260610e-005,2.603650e-007,0.000000e+000,0.000000e+000,2,7.033563e-001,1.825000e+000,,,,,,,,,,,,,,,,,,0,4.000000e+000,1.000000e+000,3,8,1.957794e+000,0,,0,
1560336007.503,,5.000000e+003,2.375701e+002,1.253626e-005,3.211787e-007,0.000000e+000,0.000000e+000,2,7.091389e-001,1.825000e+000,,,,,,,,,,,,,,,,,,0,4.000000e+000,1.000000e+000,3,8,1.967590e+000,0,,0,
1560336069.163,,5.000000e+003,2.355399e+002,1.263189e-005,4.278716e-007,0.000000e+000,0.000000e+000,2,7.044818e-001,1.825000e+000,,,,,,,,,,,,,,,,,,0,4.000000e+000,1.000000e+000,3,8,1.969803e+000,0,,0,
1560336131.903,,5.000000e+003,2.335042e+002,1.271971e-005,1.286713e-007,0.000000e+000,0.000000e+000,2,7.215632e-001,1.825000e+000,,,,,,,,,,,,,,,,,,0,4.000000e+000,1.000000e+000,3,8,2.023300e+000,0,,0,
1560336193.673,,5.000000e+003,2.314617e+002,1.261347e-005,3.187071e-007,0.000000e+000,0.000000e+000,2,7.103313e-001,1.825000e+000,,,,,,,,,,,,,,,,,,0,4.000000e+000,1.000000e+000,3,8,1.938095e+000,0,,0,
1560336255.513,,5.000000e+003,2.294252e+002,1.278322e-005,2.638060e-007,0.000000e+000,0.000000e+000,2,7.064515e-001,1.825000e+000,,,,,,,,,,,,,,,,,,0,4.000000e+000,1.000000e+000,3,8,1.958313e+000,0,,0,
1560336316.503,,5.000000e+003,2.274374e+002,1.290474e-005,3.579485e-007,0.000000e+000,0.000000e+000,2,7.214876e-001,1.825000e+000,,,,,,,,,,,,,,,,,,0,4.000000e+000,1.000000e+000,3,8,1.970795e+000,0,,0,
1560336378.813,,5.000000e+003,2.254205e+002,1.279127e-005,4.222198e-007,0.000000e+000,0.000000e+000,2,7.062643e-001,1.825000e+000,,,,,,,,,,,,,,,,,,0,4.000000e+000,1.000000e+000,3,8,1.899200e+000,0,,0,
1560336441.074,,5.000000e+003,2.233916e+002,1.311447e-005,3.735258e-007,0.000000e+000,0.000000e+000,2,7.277915e-001,1.825000e+000,,,,,,,,,,,,,,,,,,0,4.000000e+000,1.000000e+000,3,8,1.935104e+000,0,,0,
1560336502.974,,5.000000e+003,2.213798e+002,1.311757e-005,3.637284e-007,0.000000e+000,0.000000e+000,2,7.204656e-001,1.825000e+000,,,,,,,,,,,,,,,,,,0,4.000000e+000,1.000000e+000,3,8,1.944702e+000,0,,0,
1560336563.664,,5.000000e+003,2.194040e+002,1.314413e-005,3.746405e-007,0.000000e+000,0.000000e+000,2,7.228888e-001,1.825000e+000,,,,,,,,,,,,,,,,,,0,4.000000e+000,1.000000e+000,3,8,1.917694e+000,0,,0,
1560336625.064,,5.000000e+003,2.173967e+002,1.330846e-005,1.931407e-007,0.000000e+000,0.000000e+000,2,7.083246e-001,1.825000e+000,,,,,,,,,,,,,,,,,,0,4.000000e+000,1.000000e+000,3,8,1.895905e+000,0,,0,
1560336688.464,,5.000000e+003,2.153735e+002,1.307695e-005,2.498892e-007,0.000000e+000,0.000000e+000,2,7.118427e-001,1.825000e+000,,,,,,,,,,,,,,,,,,0,4.000000e+000,1.000000e+000,3,8,1.978790e+000,0,,0,
1560336750.454,,5.000000e+003,2.133003e+002,1.320500e-005,4.077544e-007,0.000000e+000,0.000000e+000,2,7.149539e-001,1.825000e+000,,,,,,,,,,,,,,,,,,0,4.000000e+000,1.000000e+000,3,8,1.942001e+000,0,,0,
1560336810.384,,5.000000e+003,2.113251e+002,1.321879e-005,3.180624e-007,0.000000e+000,0.000000e+000,2,7.251642e-001,1.825000e+000,,,,,,,,,,,,,,,,,,0,4.000000e+000,1.000000e+000,3,8,1.947403e+000,0,,0,
1560336871.954,,5.000000e+003,2.093473e+002,1.320023e-005,2.994589e-007,0.000000e+000,0.000000e+000,2,7.173321e-001,1.825000e+000,,,,,,,,,,,,,,,,,,0,4.000000e+000,1.000000e+000,3,8,1.923004e+000,0,,0,
1560336934.224,,5.000000e+003,2.073435e+002,1.361886e-005,2.916879e-007,0.000000e+000,0.000000e+000,2,7.297713e-001,1.825000e+000,,,,,,,,,,,,,,,,,,0,4.000000e+000,1.000000e+000,3,8,1.898804e+000,0,,0,
1560336994.944,,5.000000e+003,2.054431e+002,1.349051e-005,3.697338e-007,0.000000e+000,0.000000e+000,2,7.241801e-001,1.825000e+000,,,,,,,,,,,,,,,,,,0,4.000000e+000,1.000000e+000,3,8,1.833603e+000,0,,0,
1560337057.364,,5.000000e+003,2.035011e+002,1.360596e-005,3.302945e-007,0.000000e+000,0.000000e+000,2,7.320151e-001,1.825000e+000,,,,,,,,,,,,,,,,,,0,4.000000e+000,1.000000e+000,3,8,1.863800e+000,0,,0,
1560337118.715,,5.000000e+003,2.015626e+002,1.388562e-005,3.839926e-007,0.000000e+000,0.000000e+000,2,7.285422e-001,1.825000e+000,,,,,,,,,,,,,,,,,,0,4.000000e+000,1.000000e+000,3,8,1.896713e+000,0,,0,
1560337179.505,,5.000000e+003,1.996042e+002,1.361646e-005,3.226764e-007,0.000000e+000,0.000000e+000,2,7.335306e-001,1.825000e+000,,,,,,,,,,,,,,,,,,0,4.000000e+000,1.000000e+000,3,8,1.872009e+000,0,,0,
1560337240.425,,5.000000e+003,1.976598e+002,1.387090e-005,2.913307e-007,0.000000e+000,0.000000e+000,2,7.360249e-001,1.825000e+000,,,,,,,,,,,,,,,,,,0,4.000000e+000,1.000000e+000,3,8,1.931702e+000,0,,0,
1560337301.595,,5.000000e+003,1.956663e+002,1.391811e-005,2.820514e-007,0.000000e+000,0.000000e+000,2,7.438164e-001,1.825000e+000,,,,,,,,,,,,,,,,,,0,4.000000e+000,1.000000e+000,3,8,1.914307e+000,0,,0,
1560337361.965,,5.000000e+003,1.937064e+002,1.403995e-005,2.369464e-007,0.000000e+000,0.000000e+000,2,7.289639e-001,1.825000e+000,,,,,,,,,,,,,,,,,,0,4.000000e+000,1.000000e+000,3,8,1.939789e+000,0,,0,
1560337423.005,,5.000000e+003,1.916967e+002,1.407796e-005,3.102527e-007,0.000000e+000,0.000000e+000,2,7.436019e-001,1.825000e+000,,,,,,,,,,,,,,,,,,0,4.000000e+000,1.000000e+000,3,8,1.916107e+000,0,,0,
1560337484.455,,5.000000e+003,1.897094e+002,1.400839e-005,2.236029e-007,0.000000e+000,0.000000e+000,2,7.399458e-001,1.825000e+000,,,,,,,,,,,,,,,,,,0,4.000000e+000,1.000000e+000,3,8,1.992813e+000,0,,0,
1560337547.715,,5.000000e+003,1.876366e+002,1.442232e-005,4.040846e-007,0.000000e+000,0.000000e+000,2,7.442593e-001,1.825000e+000,,,,,,,,,,,,,,,,,,0,4.000000e+000,1.000000e+000,3,8,1.947311e+000,0,,0,
1560337623.075,,5.000000e+003,1.854387e+002,1.448074e-005,3.456280e-007,0.000000e+000,0.000000e+000,2,7.473250e-001,1.825000e+000,,,,,,,,,,,,,,,,,,0,4.000000e+000,1.000000e+000,3,8,2.336700e+000,0,,0,
1560337684.615,,5.000000e+003,1.832086e+002,1.435084e-005,2.821009e-007,0.000000e+000,0.000000e+000,2,7.422774e-001,1.825000e+000,,,,,,,,,,,,,,,,,,0,4.000000e+000,1.000000e+000,3,8,1.879196e+000,0,,0,
1560337745.465,,5.000000e+003,1.812722e+002,1.444968e-005,3.761714e-007,0.000000e+000,0.000000e+000,2,7.391928e-001,1.825000e+000,,,,,,,,,,,,,,,,,,0,4.000000e+000,1.000000e+000,3,8,1.908508e+000,0,,0,
1560337808.295,,5.000000e+003,1.792624e+002,1.451578e-005,2.305540e-007,0.000000e+000,0.000000e+000,2,7.495214e-001,1.825000e+000,,,,,,,,,,,,,,,,,,0,4.000000e+000,1.000000e+000,3,8,1.968399e+000,0,,0,
1560337870.006,,5.000000e+003,1.772449e+002,1.459353e-005,3.651553e-007,0.000000e+000,0.000000e+000,2,7.452323e-001,1.825000e+000,,,,,,,,,,,,,,,,,,0,4.000000e+000,1.000000e+000,3,8,1.943893e+000,0,,0,
1560337932.436,,5.000000e+003,1.752014e+002,1.464147e-005,3.005410e-007,0.000000e+000,0.000000e+000,2,7.447035e-001,1.825000e+000,,,,,,,,,,,,,,,,,,0,4.000000e+000,1.000000e+000,3,8,1.966110e+000,0,,0,
1560337993.746,,5.000000e+003,1.731779e+002,1.480270e-005,3.498975e-007,0.000000e+000,0.000000e+000,2,7.408675e-001,1.825000e+000,,,,,,,,,,,,,,,,,,0,4.000000e+000,1.000000e+000,3,8,1.978302e+000,0,,0,
1560338055.696,,5.000000e+003,1.711435e+002,1.486669e-005,1.501648e-007,0.000000e+000,0.000000e+000,2,7.488280e-001,1.825000e+000,,,,,,,,,,,,,,,,,,0,4.000000e+000,1.000000e+000,3,8,1.981506e+000,0,,0,
1560338118.586,,5.000000e+003,1.690958e+002,1.490913e-005,2.685486e-007,0.000000e+000,0.000000e+000,2,7.544794e-001,1.825000e+000,,,,,,,,,,,,,,,,,,0,4.000000e+000,1.000000e+000,3,8,1.989807e+000,0,,0,
1560338180.136,,5.000000e+003,1.670757e+002,1.514264e-005,2.197473e-007,0.000000e+000,0.000000e+000,2,7.554279e-001,1.825000e+000,,,,,,,,,,,,,,,,,,0,4.000000e+000,1.000000e+000,3,8,1.931808e+000,0,,0,
1560338243.276,,5.000000e+003,1.650653e+002,1.536136e-005,3.679498e-007,0.000000e+000,0.000000e+000,2,7.694685e-001,1.825000e+000,,,,,,,,,,,,,,,,,,0,4.000000e+000,1.000000e+000,3,8,1.928604e+000,0,,0,
1560338304.506,,5.000000e+003,1.630604e+002,1.535433e-005,1.727039e-007,0.000000e+000,0.000000e+000,2,7.672293e-001,1.825000e+000,,,,,,,,,,,,,,,,,,0,4.000000e+000,1.000000e+000,3,8,1.858200e+000,0,,0,
1560338365.736,,5.000000e+003,1.610843e+002,1.529587e-005,1.959912e-007,0.000000e+000,0.000000e+000,2,7.480049e-001,1.825000e+000,,,,,,,,,,,,,,,,,,0,4.000000e+000,1.000000e+000,3,8,1.916992e+000,0,,0,
1560338427.086,,5.000000e+003,1.590922e+002,1.540554e-005,2.795579e-007,0.000000e+000,0.000000e+000,2,7.636474e-001,1.825000e+000,,,,,,,,,,,,,,,,,,0,4.000000e+000,1.000000e+000,3,8,1.922104e+000,0,,0,
1560338488.706,,5.000000e+003,1.570879e+002,1.545588e-005,2.006287e-007,0.000000e+000,0.000000e+000,2,7.620261e-001,1.825000e+000,,,,,,,,,,,,,,,,,,0,4.000000e+000,1.000000e+000,3,8,1.936401e+000,0,,0,
1560338550.096,,5.000000e+003,1.550875e+002,1.548548e-005,3.746883e-007,0.000000e+000,0.000000e+000,2,7.601645e-001,1.825000e+000,,,,,,,,,,,,,,,,,,0,4.000000e+000,1.000000e+000,3,8,1.964706e+000,0,,0,
1560338612.547,,5.000000e+003,1.530430e+002,1.601458e-005,2.147974e-007,0.000000e+000,0.000000e+000,2,7.731442e-001,1.825000e+000,,,,,,,,,,,,,,,,,,0,4.000000e+000,1.000000e+000,3,8,1.979401e+000,0,,0,
1560338674.627,,5.000000e+003,1.509989e+002,1.585782e-005,2.688045e-007,0.000000e+000,0.000000e+000,2,7.692580e-001,1.825000e+000,,,,,,,,,,,,,,,,,,0,4.000000e+000,1.000000e+000,3,8,1.922302e+000,0,,0,
1560338735.887,,5.000000e+003,1.489767e+002,1.593315e-005,3.156039e-007,0.000000e+000,0.000000e+000,2,7.661179e-001,1.825000e+000,,,,,,,,,,,,,,,,,,0,4.000000e+000,1.000000e+000,3,8,1.964005e+000,0,,0,
1560338797.827,,5.000000e+003,1.469431e+002,1.597308e-005,2.858552e-007,0.000000e+000,0.000000e+000,2,7.775333e-001,1.825000e+000,,,,,,,,,,,,,,,,,,0,4.000000e+000,1.000000e+000,3,8,1.964310e+000,0,,0,
1560338859.487,,5.000000e+003,1.449250e+002,1.607406e-005,1.977607e-007,0.000000e+000,0.000000e+000,2,7.807954e-001,1.825000e+000,,,,,,,,,,,,,,,,,,0,4.000000e+000,1.000000e+000,3,8,1.949799e+000,0,,0,
1560338920.467,,5.000000e+003,1.429390e+002,1.615417e-005,2.749456e-007,0.000000e+000,0.000000e+000,2,7.696633e-001,1.825000e+000,,,,,,,,,,,,,,,,,,0,4.000000e+000,1.000000e+000,3,8,1.901993e+000,0,,0,
1560338980.967,,5.000000e+003,1.410248e+002,1.635919e-005,2.396729e-007,0.000000e+000,0.000000e+000,2,7.665867e-001,1.825000e+000,,,,,,,,,,,,,,,,,,0,4.000000e+000,1.000000e+000,3,8,1.877701e+000,0,,0,
1560339042.817,,5.000000e+003,1.390550e+002,1.650954e-005,2.710361e-007,0.000000e+000,0.000000e+000,2,7.732786e-001,1.825000e+000,,,,,,,,,,,,,,,,,,0,4.000000e+000,1.000000e+000,3,8,1.905594e+000,0,,0,
1560339103.337,,5.000000e+003,1.370918e+002,1.650343e-005,2.355393e-007,0.000000e+000,0.000000e+000,2,7.751814e-001,1.825000e+000,,,,,,,,,,,,,,,,,,0,4.000000e+000,1.000000e+000,3,8,1.918610e+000,0,,0,
1560339164.567,,5.000000e+003,1.351102e+002,1.674855e-005,2.122268e-007,0.000000e+000,0.000000e+000,2,7.781878e-001,1.825000e+000,,,,,,,,,,,,,,,,,,0,4.000000e+000,1.000000e+000,3,8,1.947601e+000,0,,0,
1560339226.247,,5.000000e+003,1.331047e+002,1.689254e-005,2.228041e-007,0.000000e+000,0.000000e+000,2,7.823094e-001,1.825000e+000,,,,,,,,,,,,,,,,,,0,4.000000e+000,1.000000e+000,3,8,1.973404e+000,0,,0,
1560339288.458,,5.000000e+003,1.310458e+002,1.700135e-005,3.438387e-007,0.000000e+000,0.000000e+000,2,7.745282e-001,1.825000e+000,,,,,,,,,,,,,,,,,,0,4.000000e+000,1.000000e+000,3,8,1.993805e+000,0,,0,
1560339351.308,,5.000000e+003,1.289961e+002,1.700449e-005,2.456158e-007,0.000000e+000,0.000000e+000,2,7.882909e-001,1.825000e+000,,,,,,,,,,,,,,,,,,0,4.000000e+000,1.000000e+000,3,8,2.006096e+000,0,,0,
1560339412.508,,5.000000e+003,1.269474e+002,1.731482e-005,2.608784e-007,0.000000e+000,0.000000e+000,2,7.864983e-001,1.825000e+000,,,,,,,,,,,,,,,,,,0,4.000000e+000,1.000000e+000,3,8,1.966499e+000,0,,0,
1560339473.938,,5.000000e+003,1.248906e+002,1.734667e-005,2.112508e-007,0.000000e+000,0.000000e+000,2,7.909243e-001,1.825000e+000,,,,,,,,,,,,,,,,,,0,4.000000e+000,1.000000e+000,3,8,1.939896e+000,0,,0,
1560339535.458,,5.000000e+003,1.228571e+002,1.737653e-005,1.731131e-007,0.000000e+000,0.000000e+000,2,7.850183e-001,1.825000e+000,,,,,,,,,,,,,,,,,,0,4.000000e+000,1.000000e+000,3,8,1.940498e+000,0,,0,
1560339596.958,,5.000000e+003,1.208521e+002,1.771734e-005,2.729599e-007,0.000000e+000,0.000000e+000,2,7.958015e-001,1.825000e+000,,,,,,,,,,,,,,,,,,0,4.000000e+000,1.000000e+000,3,8,1.954399e+000,0,,0,
1560339660.368,,5.000000e+003,1.187928e+002,1.783297e-005,2.922225e-007,0.000000e+000,0.000000e+000,2,7.945976e-001,1.825000e+000,,,,,,,,,,,,,,,,,,0,4.000000e+000,1.000000e+000,3,8,1.951897e+000,0,,0,
1560339723.118,,5.000000e+003,1.167477e+002,1.789529e-005,1.982421e-007,0.000000e+000,0.000000e+000,2,7.942881e-001,1.825000e+000,,,,,,,,,,,,,,,,,,0,4.000000e+000,1.000000e+000,3,8,1.962593e+000,0,,0,
1560339784.338,,5.000000e+003,1.147470e+002,1.810987e-005,2.360903e-007,0.000000e+000,0.000000e+000,2,7.932567e-001,1.825000e+000,,,,,,,,,,,,,,,,,,0,4.000000e+000,1.000000e+000,3,8,1.885399e+000,0,,0,
1560339845.368,,5.000000e+003,1.127856e+002,1.833133e-005,1.682840e-007,0.000000e+000,0.000000e+000,2,7.970902e-001,1.825000e+000,,,,,,,,,,,,,,,,,,0,4.000000e+000,1.000000e+000,3,8,1.934097e+000,0,,0,
1560339908.598,,5.000000e+003,1.107411e+002,1.838493e-005,1.654930e-007,0.000000e+000,0.000000e+000,2,7.993797e-001,1.825000e+000,,,,,,,,,,,,,,,,,,0,4.000000e+000,1.000000e+000,3,8,2.041603e+000,0,,0,
1560339970.278,,5.000000e+003,1.086501e+002,1.857848e-005,2.217886e-007,0.000000e+000,0.000000e+000,2,8.041855e-001,1.825000e+000,,,,,,,,,,,,,,,,,,0,4.000000e+000,1.000000e+000,3,8,1.993896e+000,0,,0,
1560340033.129,,5.000000e+003,1.065541e+002,1.881216e-005,2.055823e-007,0.000000e+000,0.000000e+000,2,8.028085e-001,1.825000e+000,,,,,,,,,,,,,,,,,,0,4.000000e+000,1.000000e+000,3,8,2.023903e+000,0,,0,
1560340096.299,,5.000000e+003,1.044358e+002,1.884549e-005,2.485658e-007,0.000000e+000,0.000000e+000,2,8.101454e-001,1.825000e+000,,,,,,,,,,,,,,,,,,0,4.000000e+000,1.000000e+000,3,8,2.035294e+000,0,,0,
1560340158.709,,5.000000e+003,1.023167e+002,1.918418e-005,1.549593e-007,0.000000e+000,0.000000e+000,2,8.121800e-001,1.825000e+000,,,,,,,,,,,,,,,,,,0,4.000000e+000,1.000000e+000,3,8,2.002800e+000,0,,0,
1560340220.619,,5.000000e+003,1.002320e+002,1.920948e-005,2.079615e-007,0.000000e+000,0.000000e+000,2,8.131646e-001,1.825000e+000,,,,,,,,,,,,,,,,,,0,4.000000e+000,1.000000e+000,3,8,2.006714e+000,0,,0,
1560340282.519,,5.000000e+003,9.812815e+001,1.954261e-005,1.781537e-007,0.000000e+000,0.000000e+000,2,8.149100e-001,1.825000e+000,,,,,,,,,,,,,,,,,,0,4.000000e+000,1.000000e+000,3,8,1.980415e+000,0,,0,
1560340344.819,,5.000000e+003,9.604877e+001,1.971363e-005,1.907633e-007,0.000000e+000,0.000000e+000,2,8.158638e-001,1.825000e+000,,,,,,,,,,,,,,,,,,0,4.000000e+000,1.000000e+000,3,8,2.013130e+000,0,,0,
1560340407.429,,5.000000e+003,9.395186e+001,1.983651e-005,3.273639e-007,0.000000e+000,0.000000e+000,2,8.212847e-001,1.825000e+000,,,,,,,,,,,,,,,,,,0,4.000000e+000,1.000000e+000,3,8,2.036911e+000,0,,0,
1560340469.569,,5.000000e+003,9.184306e+001,2.012656e-005,1.292383e-007,0.000000e+000,0.000000e+000,2,8.165327e-001,1.825000e+000,,,,,,,,,,,,,,,,,,0,4.000000e+000,1.000000e+000,3,8,1.991989e+000,0,,0,
1560340532.949,,5.000000e+003,8.968449e+001,2.027649e-005,1.168363e-007,0.000000e+000,0.000000e+000,2,8.193905e-001,1.825000e+000,,,,,,,,,,,,,,,,,,0,4.000000e+000,1.000000e+000,3,8,2.064285e+000,0,,0,
1560340596.049,,5.000000e+003,8.751856e+001,2.049679e-005,1.887774e-007,0.000000e+000,0.000000e+000,2,8.240334e-001,1.825000e+000,,,,,,,,,,,,,,,,,,0,4.000000e+000,1.000000e+000,3,8,2.054054e+000,0,,0,
1560340658.449,,5.000000e+003,8.534398e+001,2.071149e-005,9.945607e-008,0.000000e+000,0.000000e+000,2,8.252717e-001,1.825000e+000,,,,,,,,,,,,,,,,,,0,4.000000e+000,1.000000e+000,3,8,2.041122e+000,0,,0,
1560340721.109,,5.000000e+003,8.316837e+001,2.097538e-005,8.629969e-008,0.000000e+000,0.000000e+000,2,8.274396e-001,1.825000e+000,,,,,,,,,,,,,,,,,,0,4.000000e+000,1.000000e+000,3,8,2.098022e+000,0,,0,
1560340783.520,,5.000000e+003,8.100852e+001,2.123058e-005,1.563749e-007,0.000000e+000,0.000000e+000,2,8.283687e-001,1.825000e+000,,,,,,,,,,,,,,,,,,0,4.000000e+000,1.000000e+000,3,8,2.057228e+000,0,,0,
1560340847.380,,5.000000e+003,7.881293e+001,2.141709e-005,8.196196e-008,0.000000e+000,0.000000e+000,2,8.302355e-001,1.825000e+000,,,,,,,,,,,,,,,,,,0,4.000000e+000,1.000000e+000,3,8,2.105194e+000,0,,0,
1560340909.790,,5.000000e+003,7.662444e+001,2.170565e-005,1.787108e-007,0.000000e+000,0.000000e+000,2,8.342353e-001,1.825000e+000,,,,,,,,,,,,,,,,,,0,4.000000e+000,1.000000e+000,3,8,2.112480e+000,0,,0,
1560340972.720,,5.000000e+003,7.440103e+001,2.192450e-005,1.302925e-007,0.000000e+000,0.000000e+000,2,8.356134e-001,1.825000e+000,,,,,,,,,,,,,,,,,,0,4.000000e+000,1.000000e+000,3,8,2.130669e+000,0,,0,
1560341035.140,,5.000000e+003,7.219704e+001,2.221454e-005,1.100347e-007,0.000000e+000,0.000000e+000,2,8.368014e-001,1.825000e+000,,,,,,,,,,,,,,,,,,0,4.000000e+000,1.000000e+000,3,8,2.085861e+000,0,,0,
1560341098.350,,5.000000e+003,6.997160e+001,2.233790e-005,5.179663e-008,0.000000e+000,0.000000e+000,2,8.365400e-001,1.825000e+000,,,,,,,,,,,,,,,,,,0,4.000000e+000,1.000000e+000,3,8,2.137779e+000,0,,0,
1560341161.470,,5.000000e+003,6.771107e+001,2.269179e-005,1.435052e-007,0.000000e+000,0.000000e+000,2,8.418881e-001,1.825000e+000,,,,,,,,,,,,,,,,,,0,4.000000e+000,1.000000e+000,3,8,2.162430e+000,0,,0,
1560341224.400,,5.000000e+003,6.542245e+001,2.287603e-005,9.105834e-008,0.000000e+000,0.000000e+000,2,8.413388e-001,1.825000e+000,,,,,,,,,,,,,,,,,,0,4.000000e+000,1.000000e+000,3,8,2.220871e+000,0,,0,
1560341287.010,,5.000000e+003,6.311151e+001,2.299575e-005,9.121349e-008,0.000000e+000,0.000000e+000,2,8.430285e-001,1.825000e+000,,,,,,,,,,,,,,,,,,0,4.000000e+000,1.000000e+000,3,8,2.222450e+000,0,,0,
1560341350.040,,5.000000e+003,6.077058e+001,2.322591e-005,6.488190e-008,0.000000e+000,0.000000e+000,2,8.439329e-001,1.825000e+000,,,,,,,,,,,,,,,,,,0,4.000000e+000,1.000000e+000,3,8,2.200539e+000,0,,0,
1560341414.000,,5.000000e+003,5.841344e+001,2.318033e-005,7.871856e-008,0.000000e+000,0.000000e+000,2,8.442331e-001,1.825000e+000,,,,,,,,,,,,,,,,,,0,4.000000e+000,1.000000e+000,3,8,2.298168e+000,0,,0,
1560341476.411,,5.000000e+003,5.604424e+001,2.311685e-005,7.607899e-008,0.000000e+000,0.000000e+000,2,8.446012e-001,1.825000e+000,,,,,,,,,,,,,,,,,,0,4.000000e+000,1.000000e+000,3,8,2.223221e+000,0,,0,
1560341539.301,,5.000000e+003,5.371918e+001,2.307976e-005,7.366568e-008,0.000000e+000,0.000000e+000,2,8.430510e-001,1.825000e+000,,,,,,,,,,,,,,,,,,0,4.000000e+000,1.000000e+000,3,8,2.233871e+000,0,,0,
1560341601.451,,5.000000e+003,5.137296e+001,2.300997e-005,5.587320e-008,0.000000e+000,0.000000e+000,2,8.422246e-001,1.825000e+000,,,,,,,,,,,,,,,,,,0,4.000000e+000,1.000000e+000,3,8,2.218040e+000,0,,0,
1560341664.171,,5.000000e+003,4.902839e+001,2.299211e-005,7.154957e-008,0.000000e+000,0.000000e+000,2,8.425544e-001,1.825000e+000,,,,,,,,,,,,,,,,,,0,4.000000e+000,1.000000e+000,3,8,2.265781e+000,0,,0,
1560341726.801,,5.000000e+003,4.665831e+001,2.289603e-005,5.909979e-008,0.000000e+000,0.000000e+000,2,8.422911e-001,1.825000e+000,,,,,,,,,,,,,,,,,,0,4.000000e+000,1.000000e+000,3,8,2.291901e+000,0,,0,
1560341790.491,,5.000000e+003,4.423592e+001,2.283502e-005,4.993286e-008,0.000000e+000,0.000000e+000,2,8.419624e-001,1.825000e+000,,,,,,,,,,,,,,,,,,0,4.000000e+000,1.000000e+000,3,8,2.321110e+000,0,,0,
1560341853.941,,5.000000e+003,4.183202e+001,2.279283e-005,5.209120e-008,0.000000e+000,0.000000e+000,2,8.417954e-001,1.825000e+000,,,,,,,,,,,,,,,,,,0,4.000000e+000,1.000000e+000,3,8,2.280079e+000,0,,0,
1560341916.851,,5.000000e+003,3.942045e+001,2.271574e-005,3.533140e-008,0.000000e+000,0.000000e+000,2,8.407169e-001,1.825000e+000,,,,,,,,,,,,,,,,,,0,4.000000e+000,1.000000e+000,3,8,2.335808e+000,0,,0,
1560341979.591,,5.000000e+003,3.704611e+001,2.265079e-005,4.697664e-008,0.000000e+000,0.000000e+000,2,8.408759e-001,1.825000e+000,,,,,,,,,,,,,,,,,,0,4.000000e+000,1.000000e+000,3,8,2.234810e+000,0,,0,
1560342043.591,,5.000000e+003,3.464420e+001,2.258907e-005,3.566160e-008,0.000000e+000,0.000000e+000,2,8.401381e-001,1.825000e+000,,,,,,,,,,,,,,,,,,0,4.000000e+000,1.000000e+000,3,8,2.302807e+000,0,,0,
1560342108.101,,5.000000e+003,3.230247e+001,2.252700e-005,3.396533e-008,0.000000e+000,0.000000e+000,2,8.393962e-001,1.825000e+000,,,,,,,,,,,,,,,,,,0,4.000000e+000,1.000000e+000,3,8,2.173090e+000,0,,0,
1560342171.201,,5.000000e+003,3.008117e+001,2.245007e-005,2.623388e-008,0.000000e+000,0.000000e+000,2,8.389738e-001,1.825000e+000,,,,,,,,,,,,,,,,,,0,4.000000e+000,1.000000e+000,3,8,2.154039e+000,0,,0,
1560342233.552,,5.000000e+003,2.789085e+001,2.238584e-005,3.187348e-008,0.000000e+000,0.000000e+000,2,8.384337e-001,1.825000e+000,,,,,,,,,,,,,,,,,,0,4.000000e+000,1.000000e+000,3,8,2.081181e+000,0,,0,
1560342296.452,,5.000000e+003,2.576699e+001,2.231757e-005,2.445681e-008,0.000000e+000,0.000000e+000,2,8.383546e-001,1.825000e+000,,,,,,,,,,,,,,,,,,0,4.000000e+000,1.000000e+000,3,8,2.091900e+000,0,,0,
1560342360.282,,5.000000e+003,2.323847e+001,2.222996e-005,2.777753e-008,0.000000e+000,0.000000e+000,2,8.376896e-001,1.825000e+000,,,,,,,,,,,,,,,,,,0,4.000000e+000,1.000000e+000,3,8,1.713150e+000,0,,0,
1560342422.952,,5.000000e+003,2.138910e+001,2.220342e-005,2.614880e-008,0.000000e+000,0.000000e+000,2,8.374799e-001,1.825000e+000,,,,,,,,,,,,,,,,,,0,4.000000e+000,1.000000e+000,3,8,2.018450e+000,0,,0,
1560342485.342,,5.000000e+003,1.925241e+001,2.212508e-005,2.367521e-008,0.000000e+000,0.000000e+000,2,8.365041e-001,1.825000e+000,,,,,,,,,,,,,,,,,,0,4.000000e+000,1.000000e+000,3,8,2.016470e+000,0,,0,
1560342549.502,,5.000000e+003,1.711792e+001,2.206295e-005,2.883613e-008,0.000000e+000,0.000000e+000,2,8.386877e-001,1.825000e+000,,,,,,,,,,,,,,,,,,0,4.000000e+000,1.000000e+000,3,8,2.104420e+000,0,,0,
1560342612.902,,5.000000e+003,1.491955e+001,2.200429e-005,1.048492e-008,0.000000e+000,0.000000e+000,2,8.387424e-001,1.825000e+000,,,,,,,,,,,,,,,,,,0,4.000000e+000,1.000000e+000,3,8,2.086120e+000,0,,0,
1560342677.302,,5.000000e+003,1.270681e+001,2.196914e-005,1.954883e-008,0.000000e+000,0.000000e+000,2,8.384068e-001,1.825000e+000,,,,,,,,,,,,,,,,,,0,4.000000e+000,1.000000e+000,3,8,2.159531e+000,0,,0,
1560342740.232,,5.000000e+003,1.054299e+001,2.193580e-005,1.991405e-008,0.000000e+000,0.000000e+000,2,8.374657e-001,1.825000e+000,,,,,,,,,,,,,,,,,,0,4.000000e+000,1.000000e+000,3,8,1.895736e+000,0,,0,
1560342802.852,,5.000000e+003,8.651353e+000,2.192044e-005,1.604621e-008,0.000000e+000,0.000000e+000,2,8.381268e-001,1.825000e+000,,,,,,,,,,,,,,,,,,0,4.000000e+000,1.000000e+000,3,8,1.916038e+000,0,,0,
1560342865.052,,5.000000e+003,6.824278e+000,2.190551e-005,1.146769e-008,0.000000e+000,0.000000e+000,2,8.381587e-001,1.825000e+000,,,,,,,,,,,,,,,,,,0,4.000000e+000,1.000000e+000,3,8,1.590161e+000,0,,0,
1560342927.233,,5.000000e+003,4.964540e+000,2.190823e-005,1.354659e-008,0.000000e+000,0.000000e+000,2,8.389965e-001,1.825000e+000,,,,,,,,,,,,,,,,,,0,4.000000e+000,1.000000e+000,3,8,1.933542e+000,0,,0,
1560343091.833,,5.000000e+003,3.998471e+000,2.189596e-005,2.049592e-008,0.000000e+000,0.000000e+000,2,8.378714e-001,1.825000e+000,,,,,,,,,,,,,,,,,,0,4.000000e+000,1.000000e+000,3,8,3.780127e-002,0,,0,
1560343162.633,,5.000000e+003,3.974958e+000,2.191306e-005,1.343668e-008,0.000000e+000,0.000000e+000,2,8.382648e-001,1.825000e+000,,,,,,,,,,,,,,,,,,0,4.000000e+000,1.000000e+000,3,8,1.009529e-001,0,,0,
1560343223.983,,5.000000e+003,3.978321e+000,2.192814e-005,1.419990e-008,0.000000e+000,0.000000e+000,2,8.382980e-001,1.825000e+000,,,,,,,,,,,,,,,,,,0,4.000000e+000,1.000000e+000,3,8,5.230689e-002,0,,0,
1560343285.163,,5.000000e+003,3.988533e+000,2.193038e-005,1.433363e-008,0.000000e+000,0.000000e+000,2,8.382395e-001,1.825000e+000,,,,,,,,,,,,,,,,,,0,4.000000e+000,1.000000e+000,3,8,1.692319e-002,0,,0,
1560343347.333,,5.000000e+003,3.994758e+000,2.192720e-005,1.437391e-008,0.000000e+000,0.000000e+000,2,8.386298e-001,1.825000e+000,,,,,,,,,,,,,,,,,,0,4.000000e+000,1.000000e+000,3,8,1.677108e-002,0,,0,
1560343408.503,,5.000000e+003,3.999345e+000,2.193892e-005,1.325434e-008,0.000000e+000,0.000000e+000,2,8.385744e-001,1.825000e+000,,,,,,,,,,,,,,,,,,0,4.000000e+000,1.000000e+000,3,8,9.547234e-003,0,,0,
1560343469.313,,5.000000e+003,4.002313e+000,2.193837e-005,1.346708e-008,0.000000e+000,0.000000e+000,2,8.386896e-001,1.825000e+000,,,,,,,,,,,,,,,,,,0,4.000000e+000,1.000000e+000,3,8,5.178213e-003,0,,0,
1560343530.063,,5.000000e+003,4.006431e+000,2.194409e-005,1.094170e-008,0.000000e+000,0.000000e+000,2,8.384358e-001,1.825000e+000,,,,,,,,,,,,,,,,,,0,4.000000e+000,1.000000e+000,3,8,5.980968e-003,0,,0,