File: examples/squid/data/H1270_Si_HoopII110_hysteresis_4 K_26072019.rso.dat
[Header]
TITLE,MPMS RSO Measurement
BYAPP,MPMS Measurement,1.1,Summary
FILEOPENTIME, 1564164248.149000 7/26/2019, 8:04:08 PM

INFO, APPNAME, MPMS MultiVu Application, Revision 1.61,  Build 082

INFO, NAME, H1270_1-10
INFO, WEIGHT, 1.000
INFO, AREA, 1.000
INFO, LENGTH, 1.000
INFO, SHAPE, 1
INFO, COMMENT,
INFO, SEQUENCE FILE: Hysteresis5T_new.seq


INFO, BACKGROUND DATA FILE:, None


STARTUPAXIS,X,4,LINEAR,AUTO,0.000000,0.000000
STARTUPAXIS,Y1,5,LINEAR,AUTO,0.000000,0.000000


STARTUPGROUP,Longitudinal
FIELDGROUP,Longitudinal,1,2,3,4,5,6,7,8,9,10,11,19,20,21,22,23,35
FIELDGROUP,Transverse,1,2,3,4,12,13,14,15,16,17,18,24,25,26,27,28,35

PLOT_APPEARANCE,ALL,HORZ_GRID_ON,VERT_GRID_ON,MARKERS_AND_LINES

[Data]
Time,Comment,Field (Oe),Temperature (K),Long Moment (emu),Long Scan Std Dev,Long Offset (cm),Long Offset Std Dev,Long Algorithm,Long Reg Fit,Long Reg Factor,Trans Moment (emu),Trans Scan Std Dev,Trans Offset (cm),Trans Offset Std Dev,Trans Algorithm,Trans Reg Fit,Trans Reg Factor,Long Moment [w/o ABS] (emu),Long Scan Std Dev [w/o ABS],Long Offset [w/o ABS] (cm),Long Offset Std Dev [w/o ABS],Long Reg Fit [w/o ABS],Trans Moment [w/o ABS] (emu),Trans Scan Std Dev [w/o ABS],Trans Offset [w/o ABS] (cm),Trans Offset Std Dev [w/o ABS],Trans Reg Fit [w/o ABS],RSO Position (deg),Amplitude (cm),Frequency,Cycles to Average,Scans per Measurement,Delta Temp (K),Error,EC Comp. Running,Using ABS,
1564164248.149,,5.000000e+004,3.998873e+000,-5.724302e-004,1.151617e-007,0.000000e+000,0.000000e+000,2,9.588249e-001,1.825000e+000,,,,,,,,,,,,,,,,,,0,4.000000e+000,5.000000e-001,4,4,7.127762e-003,0,,0,
1564164405.119,,4.500000e+004,4.008391e+000,-5.132331e-004,1.000630e-007,0.000000e+000,0.000000e+000,2,9.594995e-001,1.825000e+000,,,,,,,,,,,,,,,,,,0,4.000000e+000,5.000000e-001,4,4,9.839058e-003,0,,0,
1564164574.199,,4.000000e+004,4.009000e+000,-4.555617e-004,7.505040e-008,0.000000e+000,0.000000e+000,2,9.598394e-001,1.825000e+000,,,,,,,,,,,,,,,,,,0,4.000000e+000,5.000000e-001,4,4,1.972198e-003,0,,0,
1564164737.339,,3.500000e+004,4.003227e+000,-3.975868e-004,3.057051e-008,0.000000e+000,0.000000e+000,2,9.601418e-001,1.825000e+000,,,,,,,,,,,,,,,,,,0,4.000000e+000,5.000000e-001,4,4,8.314133e-003,0,,0,
1564164905.400,,3.000000e+004,4.003826e+000,-3.394819e-004,8.041848e-008,0.000000e+000,0.000000e+000,2,9.601733e-001,1.825000e+000,,,,,,,,,,,,,,,,,,0,4.000000e+000,5.000000e-001,4,4,8.552074e-003,0,,0,
1564165064.690,,2.500000e+004,4.003050e+000,-2.814120e-004,4.660355e-008,0.000000e+000,0.000000e+000,2,9.600326e-001,1.825000e+000,,,,,,,,,,,,,,,,,,0,4.000000e+000,5.000000e-001,4,4,8.312941e-003,0,,0,
1564165225.990,,2.000000e+004,4.003689e+000,-2.235626e-004,8.012782e-009,0.000000e+000,0.000000e+000,2,9.599476e-001,1.825000e+000,,,,,,,,,,,,,,,,,,0,4.000000e+000,5.000000e-001,4,4,8.630037e-003,0,,0,
1564165405.830,,1.500000e+004,4.005160e+000,-1.661030e-004,2.557260e-008,0.000000e+000,0.000000e+000,2,9.595538e-001,1.825000e+000,,,,,,,,,,,,,,,,,,0,4.000000e+000,5.000000e-001,4,4,1.258373e-003,0,,0,
1564165564.351,,1.000000e+004,4.002550e+000,-1.088822e-004,8.524661e-008,0.000000e+000,0.000000e+000,2,9.587967e-001,1.825000e+000,,,,,,,,,,,,,,,,,,0,4.000000e+000,5.000000e-001,4,4,9.879112e-003,0,,0,
1564165722.131,,7.500000e+003,4.004148e+000,-8.082359e-005,2.437953e-008,0.000000e+000,0.000000e+000,2,9.591792e-001,1.825000e+000,,,,,,,,,,,,,,,,,,0,4.000000e+000,5.000000e-001,4,4,3.927231e-003,0,,0,
1564165950.951,,5.000000e+003,4.006075e+000,-5.257580e-005,1.599031e-008,0.000000e+000,0.000000e+000,2,9.582984e-001,1.825000e+000,,,,,,,,,,,,,,,,,,0,4.000000e+000,5.000000e-001,4,4,2.046108e-003,0,,0,
1564166133.211,,4.000000e+003,4.004354e+000,-4.153091e-005,1.198864e-007,0.000000e+000,0.000000e+000,2,9.581155e-001,1.825000e+000,,,,,,,,,,,,,,,,,,0,4.000000e+000,5.000000e-001,4,4,3.300190e-003,0,,0,
1564166305.082,,3.000000e+003,4.004797e+000,-3.069468e-005,3.738885e-007,0.000000e+000,0.000000e+000,2,9.519773e-001,1.825000e+000,,,,,,,,,,,,,,,,,,0,4.000000e+000,5.000000e-001,4,4,3.536224e-003,0,,0,
1564166467.712,,2.000000e+003,4.002914e+000,-1.972089e-005,1.742245e-007,0.000000e+000,0.000000e+000,2,9.511234e-001,1.825000e+000,,,,,,,,,,,,,,,,,,0,4.000000e+000,5.000000e-001,4,4,1.003718e-002,0,,0,
1564166626.742,,1.800000e+003,4.003208e+000,-1.756246e-005,1.729569e-007,0.000000e+000,0.000000e+000,2,9.437715e-001,1.825000e+000,,,,,,,,,,,,,,,,,,0,4.000000e+000,5.000000e-001,4,4,9.257078e-003,0,,0,
1564166790.462,,1.700000e+003,4.003189e+000,-1.664325e-005,5.014698e-008,0.000000e+000,0.000000e+000,2,9.544030e-001,1.825000e+000,,,,,,,,,,,,,,,,,,0,4.000000e+000,5.000000e-001,4,4,9.804964e-003,0,,0,
1564166953.763,,1.600000e+003,4.003483e+000,-1.538499e-005,1.417746e-007,0.000000e+000,0.000000e+000,2,9.487246e-001,1.825000e+000,,,,,,,,,,,,,,,,,,0,4.000000e+000,5.000000e-001,4,4,1.003981e-002,0,,0,
1564167088.373,,1.500000e+003,4.002217e+000,-1.447420e-005,1.429847e-007,0.000000e+000,0.000000e+000,2,9.387753e-001,1.825000e+000,,,,,,,,,,,,,,,,,,0,4.000000e+000,5.000000e-001,4,4,9.562016e-003,0,,0,
1564167239.343,,1.400000e+003,4.002581e+000,-1.346139e-005,1.668201e-007,0.000000e+000,0.000000e+000,2,9.466420e-001,1.825000e+000,,,,,,,,,,,,,,,,,,0,4.000000e+000,5.000000e-001,4,4,1.082087e-002,0,,0,
1564167381.753,,1.300000e+003,4.002404e+000,-1.246764e-005,1.446128e-007,0.000000e+000,0.000000e+000,2,9.455339e-001,1.825000e+000,,,,,,,,,,,,,,,,,,0,4.000000e+000,5.000000e-001,4,4,9.955883e-003,0,,0,
1564167520.033,,1.200000e+003,4.002433e+000,-1.132774e-005,1.619238e-007,0.000000e+000,0.000000e+000,2,9.495449e-001,1.825000e+000,,,,,,,,,,,,,,,,,,0,4.000000e+000,5.000000e-001,4,4,1.034904e-002,0,,0,
1564167662.584,,1.100000e+003,4.002443e+000,-1.028168e-005,1.541764e-007,0.000000e+000,0.000000e+000,2,9.364214e-001,1.825000e+000,,,,,,,,,,,,,,,,,,0,4.000000e+000,5.000000e-001,4,4,9.954929e-003,0,,0,
1564167809.434,,1.000000e+003,4.002531e+000,-9.328151e-006,1.347842e-007,0.000000e+000,0.000000e+000,2,9.356731e-001,1.825000e+000,,,,,,,,,,,,,,,,,,0,4.000000e+000,5.000000e-001,4,4,1.027179e-002,0,,0,
1564167973.144,,9.000000e+002,4.003149e+000,-8.087473e-006,1.013127e-007,0.000000e+000,0.000000e+000,2,9.205006e-001,1.825000e+000,,,,,,,,,,,,,,,,,,0,4.000000e+000,5.000000e-001,4,4,9.803057e-003,0,,0,
1564168135.674,,8.000000e+002,4.003012e+000,-7.287043e-006,1.250100e-007,0.000000e+000,0.000000e+000,2,9.457510e-001,1.825000e+000,,,,,,,,,,,,,,,,,,0,4.000000e+000,5.000000e-001,4,4,9.802103e-003,0,,0,
1564168269.834,,7.000000e+002,4.001991e+000,-6.045420e-006,6.754972e-008,0.000000e+000,0.000000e+000,2,8.765364e-001,1.825000e+000,,,,,,,,,,,,,,,,,,0,4.000000e+000,5.000000e-001,4,4,9.562016e-003,0,,0,
1564168403.875,,6.000000e+002,4.001512e+000,-4.940306e-006,1.709778e-007,0.000000e+000,0.000000e+000,2,9.042710e-001,1.825000e+000,,,,,,,,,,,,,,,,,,0,4.000000e+000,5.000000e-001,4,4,9.715796e-003,0,,0,
1564168533.405,,5.000000e+002,4.001834e+000,-4.065441e-006,1.843872e-007,0.000000e+000,0.000000e+000,2,8.610998e-001,1.825000e+000,,,,,,,,,,,,,,,,,,0,4.000000e+000,5.000000e-001,4,4,9.558916e-003,0,,0,
1564168663.955,,4.500000e+002,4.001687e+000,-3.506864e-006,7.836594e-008,0.000000e+000,0.000000e+000,2,9.109427e-001,1.825000e+000,,,,,,,,,,,,,,,,,,0,4.000000e+000,5.000000e-001,4,4,9.636879e-003,0,,0,
1564168823.515,,4.000000e+002,4.002816e+000,-3.051783e-006,1.037736e-007,0.000000e+000,0.000000e+000,2,8.708266e-001,1.825000e+000,,,,,,,,,,,,,,,,,,0,4.000000e+000,5.000000e-001,4,4,9.958267e-003,0,,0,
1564168954.235,,3.500000e+002,4.002403e+000,-2.703625e-006,2.316444e-007,0.000000e+000,0.000000e+000,2,8.244625e-001,1.825000e+000,,,,,,,,,,,,,,,,,,0,4.000000e+000,5.000000e-001,4,4,1.011300e-002,0,,0,
1564169088.595,,3.000000e+002,4.001727e+000,-1.983377e-006,1.502298e-007,0.000000e+000,0.000000e+000,2,8.289810e-001,1.825000e+000,,,,,,,,,,,,,,,,,,0,4.000000e+000,5.000000e-001,4,4,9.795189e-003,0,,0,
1564169218.626,,2.500000e+002,4.001688e+000,-1.552091e-006,1.414573e-007,0.000000e+000,0.000000e+000,2,6.727726e-001,1.825000e+000,,,,,,,,,,,,,,,,,,0,4.000000e+000,5.000000e-001,4,4,9.952307e-003,0,,0,
1564169353.086,,2.000000e+002,4.001854e+000,-1.055213e-006,1.153905e-007,0.000000e+000,0.000000e+000,2,5.695797e-001,1.825000e+000,,,,,,,,,,,,,,,,,,0,4.000000e+000,5.000000e-001,4,4,1.026607e-002,0,,0,
1564169495.946,,1.500000e+002,4.002442e+000,-5.976727e-007,9.221089e-008,0.000000e+000,0.000000e+000,2,5.816791e-001,1.825000e+000,,,,,,,,,,,,,,,,,,0,4.000000e+000,5.000000e-001,4,4,1.066113e-002,0,,0,
1564169672.976,,1.000000e+002,4.003445e+000,3.385135e-008,4.700497e-008,0.000000e+000,0.000000e+000,2,0.000000e+000,1.825000e+000,,,,,,,,,,,,,,,,,,0,4.000000e+000,5.000000e-001,4,4,1.043105e-002,0,,0,
1564169837.587,,5.000000e+001,4.002699e+000,4.226401e-007,1.158613e-007,0.000000e+000,0.000000e+000,2,4.001640e-001,1.825000e+000,,,,,,,,,,,,,,,,,,0,4.000000e+000,5.000000e-001,4,4,1.058388e-002,0,,0,
1564170003.737,,0.000000e+000,4.004835e+000,8.818928e-007,3.307831e-008,0.000000e+000,0.000000e+000,2,8.057926e-001,1.825000e+000,,,,,,,,,,,,,,,,,,0,4.000000e+000,5.000000e-001,4,4,1.967430e-003,0,,0,
1564170139.017,,-5.000000e+001,4.000482e+000,1.359190e-006,9.824353e-008,0.000000e+000,0.000000e+000,2,7.921019e-001,1.825000e+000,,,,,,,,,,,,,,,,,,0,4.000000e+000,5.000000e-001,4,4,1.041508e-002,0,,0,
1564170270.827,,-1.000000e+002,4.001608e+000,1.912568e-006,1.268569e-007,0.000000e+000,0.000000e+000,2,8.926304e-001,1.825000e+000,,,,,,,,,,,,,,,,,,0,4.000000e+000,5.000000e-001,4,4,9.715319e-003,0,,0,
1564170406.657,,-1.500000e+002,4.001992e+000,2.332853e-006,1.300195e-007,0.000000e+000,0.000000e+000,2,8.912056e-001,1.825000e+000,,,,,,,,,,,,,,,,,,0,4.000000e+000,5.000000e-001,4,4,1.042628e-002,0,,0,
1564170570.968,,-2.000000e+002,4.002894e+000,2.896997e-006,5.293416e-008,0.000000e+000,0.000000e+000,2,9.130840e-001,1.825000e+000,,,,,,,,,,,,,,,,,,0,4.000000e+000,5.000000e-001,4,4,1.027179e-002,0,,0,
1564170735.278,,-2.500000e+002,4.003170e+000,3.381701e-006,4.529440e-008,0.000000e+000,0.000000e+000,2,9.309494e-001,1.825000e+000,,,,,,,,,,,,,,,,,,0,4.000000e+000,5.000000e-001,4,4,1.027489e-002,0,,0,
1564170900.048,,-3.000000e+002,4.003278e+000,3.878013e-006,7.749153e-008,0.000000e+000,0.000000e+000,2,9.313546e-001,1.825000e+000,,,,,,,,,,,,,,,,,,0,4.000000e+000,5.000000e-001,4,4,1.066780e-002,0,,0,
1564171039.568,,-3.500000e+002,4.002060e+000,4.422787e-006,2.918038e-008,0.000000e+000,0.000000e+000,2,9.315425e-001,1.825000e+000,,,,,,,,,,,,,,,,,,0,4.000000e+000,5.000000e-001,4,4,9.875774e-003,0,,0,
1564171203.828,,-4.000000e+002,4.002884e+000,4.837539e-006,4.696030e-008,0.000000e+000,0.000000e+000,2,9.422691e-001,1.825000e+000,,,,,,,,,,,,,,,,,,0,4.000000e+000,5.000000e-001,4,4,1.034999e-002,0,,0,
1564171352.589,,-4.500000e+002,4.002237e+000,5.367606e-006,3.612501e-008,0.000000e+000,0.000000e+000,2,9.420643e-001,1.825000e+000,,,,,,,,,,,,,,,,,,0,4.000000e+000,5.000000e-001,4,4,9.880304e-003,0,,0,
1564171496.849,,-5.000000e+002,4.001961e+000,5.970907e-006,2.118607e-007,0.000000e+000,0.000000e+000,2,9.163232e-001,1.825000e+000,,,,,,,,,,,,,,,,,,0,4.000000e+000,5.000000e-001,4,4,9.090185e-003,0,,0,
1564171661.919,,-6.000000e+002,4.002717e+000,6.867494e-006,5.948471e-008,0.000000e+000,0.000000e+000,2,9.381710e-001,1.825000e+000,,,,,,,,,,,,,,,,,,0,4.000000e+000,5.000000e-001,4,4,9.721994e-003,0,,0,
1564171802.199,,-7.000000e+002,4.002196e+000,7.769789e-006,3.978918e-008,0.000000e+000,0.000000e+000,2,9.309216e-001,1.825000e+000,,,,,,,,,,,,,,,,,,0,4.000000e+000,5.000000e-001,4,4,8.152962e-003,0,,0,
1564171938.479,,-8.000000e+002,4.001863e+000,8.947084e-006,3.384501e-007,0.000000e+000,0.000000e+000,2,9.197892e-001,1.825000e+000,,,,,,,,,,,,,,,,,,0,4.000000e+000,5.000000e-001,4,4,9.561300e-003,0,,0,
1564172075.250,,-9.000000e+002,4.001745e+000,9.813545e-006,7.577629e-008,0.000000e+000,0.000000e+000,2,9.375418e-001,1.825000e+000,,,,,,,,,,,,,,,,,,0,4.000000e+000,5.000000e-001,4,4,8.774042e-003,0,,0,
1564172211.550,,-1.000000e+003,4.001697e+000,1.089423e-005,3.186115e-007,0.000000e+000,0.000000e+000,2,9.039664e-001,1.825000e+000,,,,,,,,,,,,,,,,,,0,4.000000e+000,5.000000e-001,4,4,9.798050e-003,0,,0,
1564172348.060,,-1.100000e+003,4.001716e+000,1.190241e-005,3.336287e-008,0.000000e+000,0.000000e+000,2,9.467112e-001,1.825000e+000,,,,,,,,,,,,,,,,,,0,4.000000e+000,5.000000e-001,4,4,9.011984e-003,0,,0,
1564172484.370,,-1.200000e+003,4.001550e+000,1.291836e-005,5.025182e-008,0.000000e+000,0.000000e+000,2,9.395503e-001,1.825000e+000,,,,,,,,,,,,,,,,,,0,4.000000e+000,5.000000e-001,4,4,8.775949e-003,0,,0,
1564172619.440,,-1.300000e+003,4.001942e+000,1.396046e-005,1.430647e-007,0.000000e+000,0.000000e+000,2,9.266984e-001,1.825000e+000,,,,,,,,,,,,,,,,,,0,4.000000e+000,5.000000e-001,4,4,8.777142e-003,0,,0,
1564172771.451,,-1.400000e+003,4.002286e+000,1.500436e-005,3.081451e-007,0.000000e+000,0.000000e+000,2,9.328969e-001,1.825000e+000,,,,,,,,,,,,,,,,,,0,4.000000e+000,5.000000e-001,4,4,9.640932e-003,0,,0,
1564172908.031,,-1.500000e+003,4.002137e+000,1.614649e-005,4.150205e-007,0.000000e+000,0.000000e+000,2,9.247000e-001,1.825000e+000,,,,,,,,,,,,,,,,,,0,4.000000e+000,5.000000e-001,4,4,8.384943e-003,0,,0,
1564173049.041,,-1.600000e+003,4.001432e+000,1.878470e-005,3.669752e-006,0.000000e+000,0.000000e+000,2,7.980002e-001,1.825000e+000,,,,,,,,,,,,,,,,,,0,4.000000e+000,5.000000e-001,4,4,8.618832e-003,0,,0,
1564173202.391,,-1.700000e+003,4.001922e+000,1.802484e-005,9.115466e-008,0.000000e+000,0.000000e+000,2,9.354355e-001,1.825000e+000,,,,,,,,,,,,,,,,,,0,4.000000e+000,5.000000e-001,4,4,8.697987e-003,0,,0,
1564173339.181,,-1.800000e+003,4.001775e+000,1.944491e-005,5.603342e-007,0.000000e+000,0.000000e+000,2,9.122838e-001,1.825000e+000,,,,,,,,,,,,,,,,,,0,4.000000e+000,5.000000e-001,4,4,9.171009e-003,0,,0,
1564173479.762,,-2.000000e+003,4.002040e+000,2.132239e-005,5.485624e-007,0.000000e+000,0.000000e+000,2,9.227127e-001,1.825000e+000,,,,,,,,,,,,,,,,,,0,4.000000e+000,5.000000e-001,4,4,9.090900e-003,0,,0,
1564173640.042,,-3.000000e+003,4.002472e+000,3.196210e-005,3.242542e-007,0.000000e+000,0.000000e+000,2,9.614645e-001,1.825000e+000,,,,,,,,,,,,,,,,,,0,4.000000e+000,5.000000e-001,4,4,9.563923e-003,0,,0,
1564173809.282,,-4.000000e+003,4.004659e+000,4.300801e-005,1.525631e-007,0.000000e+000,0.000000e+000,2,9.615746e-001,1.825000e+000,,,,,,,,,,,,,,,,,,0,4.000000e+000,5.000000e-001,4,4,2.830982e-003,0,,0,
1564173977.312,,-5.000000e+003,4.001843e+000,5.388566e-005,5.922333e-008,0.000000e+000,0.000000e+000,2,9.620247e-001,1.825000e+000,,,,,,,,,,,,,,,,,,0,4.000000e+000,5.000000e-001,4,4,1.065898e-002,0,,0,
1564174139.172,,-7.500000e+003,4.002197e+000,8.219540e-005,9.355215e-008,0.000000e+000,0.000000e+000,2,9.615341e-001,1.825000e+000,,,,,,,,,,,,,,,,,,0,4.000000e+000,5.000000e-001,4,4,9.564161e-003,0,,0,
1564174284.963,,-1.000000e+004,4.001539e+000,1.105357e-004,4.739907e-007,0.000000e+000,0.000000e+000,2,9.630134e-001,1.825000e+000,,,,,,,,,,,,,,,,,,0,4.000000e+000,5.000000e-001,4,4,8.852005e-003,0,,0,
1564174463.823,,-1.500000e+004,4.004708e+000,1.671701e-004,4.682378e-007,0.000000e+000,0.000000e+000,2,9.606228e-001,1.825000e+000,,,,,,,,,,,,,,,,,,0,4.000000e+000,5.000000e-001,4,4,2.752781e-003,0,,0,
1564174612.043,,-2.000000e+004,4.001402e+000,2.246738e-004,8.155554e-007,0.000000e+000,0.000000e+000,2,9.607815e-001,1.825000e+000,,,,,,,,,,,,,,,,,,0,4.000000e+000,5.000000e-001,4,4,9.952307e-003,0,,0,
1564174765.903,,-2.500000e+004,4.002040e+000,2.816562e-004,4.966198e-007,0.000000e+000,0.000000e+000,2,9.612362e-001,1.825000e+000,,,,,,,,,,,,,,,,,,0,4.000000e+000,5.000000e-001,4,4,8.387089e-003,0,,0,
1564174920.174,,-3.000000e+004,4.002628e+000,3.389211e-004,5.942464e-007,0.000000e+000,0.000000e+000,2,9.609522e-001,1.825000e+000,,,,,,,,,,,,,,,,,,0,4.000000e+000,5.000000e-001,4,4,9.095907e-003,0,,0,
1564175084.454,,-3.500000e+004,4.002560e+000,3.973600e-004,9.174481e-007,0.000000e+000,0.000000e+000,2,9.644496e-001,1.825000e+000,,,,,,,,,,,,,,,,,,0,4.000000e+000,5.000000e-001,4,4,8.468151e-003,0,,0,
1564175233.474,,-4.000000e+004,4.002364e+000,4.560397e-004,6.824106e-007,0.000000e+000,0.000000e+000,2,9.658335e-001,1.825000e+000,,,,,,,,,,,,,,,,,,0,4.000000e+000,5.000000e-001,4,4,8.467197e-003,0,,0,
1564175399.174,,-4.500000e+004,4.002502e+000,5.119936e-004,8.578981e-007,0.000000e+000,0.000000e+000,2,9.642808e-001,1.825000e+000,,,,,,,,,,,,,,,,,,0,4.000000e+000,5.000000e-001,4,4,9.797096e-003,0,,0,
1564175557.564,,-5.000000e+004,4.002187e+000,5.706301e-004,6.086446e-007,0.000000e+000,0.000000e+000,2,9.637485e-001,1.825000e+000,,,,,,,,,,,,,,,,,,0,4.000000e+000,5.000000e-001,4,4,8.388042e-003,0,,0,
1564175616.584,,-5.000000e+004,4.004354e+000,5.709690e-004,1.842554e-006,0.000000e+000,0.000000e+000,2,9.651274e-001,1.825000e+000,,,,,,,,,,,,,,,,,,0,4.000000e+000,5.000000e-001,4,4,1.965046e-003,0,,0,
1564175773.795,,-4.500000e+004,4.000687e+000,5.136688e-004,1.322728e-006,0.000000e+000,0.000000e+000,2,9.663121e-001,1.825000e+000,,,,,,,,,,,,,,,,,,0,4.000000e+000,5.000000e-001,4,4,1.010513e-002,0,,0,
1564175941.845,,-4.000000e+004,4.002766e+000,4.555898e-004,4.702614e-007,0.000000e+000,0.000000e+000,2,9.651359e-001,1.825000e+000,,,,,,,,,,,,,,,,,,0,4.000000e+000,5.000000e-001,4,4,9.097099e-003,0,,0,
1564176100.995,,-3.500000e+004,4.002609e+000,3.985960e-004,4.702301e-007,0.000000e+000,0.000000e+000,2,9.683014e-001,1.825000e+000,,,,,,,,,,,,,,,,,,0,4.000000e+000,5.000000e-001,4,4,8.392096e-003,0,,0,
1564176263.775,,-3.000000e+004,4.002363e+000,3.394898e-004,4.298383e-007,0.000000e+000,0.000000e+000,2,9.673352e-001,1.825000e+000,,,,,,,,,,,,,,,,,,0,4.000000e+000,5.000000e-001,4,4,9.333134e-003,0,,0,
1564176417.326,,-2.500000e+004,4.002187e+000,2.813342e-004,7.551998e-007,0.000000e+000,0.000000e+000,2,9.663495e-001,1.825000e+000,,,,,,,,,,,,,,,,,,0,4.000000e+000,5.000000e-001,4,4,9.330988e-003,0,,0,
1564176578.146,,-2.000000e+004,4.002207e+000,2.238822e-004,4.209145e-007,0.000000e+000,0.000000e+000,2,9.640220e-001,1.825000e+000,,,,,,,,,,,,,,,,,,0,4.000000e+000,5.000000e-001,4,4,8.387327e-003,0,,0,
1564176733.606,,-1.500000e+004,4.002079e+000,1.667085e-004,6.980925e-007,0.000000e+000,0.000000e+000,2,9.609401e-001,1.825000e+000,,,,,,,,,,,,,,,,,,0,4.000000e+000,5.000000e-001,4,4,7.994890e-003,0,,0,
1564176888.376,,-1.000000e+004,4.002157e+000,1.095335e-004,1.816126e-007,0.000000e+000,0.000000e+000,2,9.599667e-001,1.825000e+000,,,,,,,,,,,,,,,,,,0,4.000000e+000,5.000000e-001,4,4,9.408951e-003,0,,0,
1564177046.736,,-7.500000e+003,4.002511e+000,8.073508e-005,1.414939e-007,0.000000e+000,0.000000e+000,2,9.597119e-001,1.825000e+000,,,,,,,,,,,,,,,,,,0,4.000000e+000,5.000000e-001,4,4,8.543015e-003,0,,0,
1564177252.797,,-5.000000e+003,4.003315e+000,5.255361e-005,1.865350e-007,0.000000e+000,0.000000e+000,2,9.567190e-001,1.825000e+000,,,,,,,,,,,,,,,,,,0,4.000000e+000,5.000000e-001,4,4,9.255886e-003,0,,0,
1564177444.957,,-4.000000e+003,4.004727e+000,4.142810e-005,1.004641e-007,0.000000e+000,0.000000e+000,2,9.608625e-001,1.825000e+000,,,,,,,,,,,,,,,,,,0,4.000000e+000,5.000000e-001,4,4,2.045155e-003,0,,0,
1564177622.887,,-3.000000e+003,4.002606e+000,3.060824e-005,1.902901e-007,0.000000e+000,0.000000e+000,2,9.544149e-001,1.825000e+000,,,,,,,,,,,,,,,,,,0,4.000000e+000,5.000000e-001,4,4,4.471779e-003,0,,0,
1564177792.587,,-2.000000e+003,4.002910e+000,1.965275e-005,1.662152e-007,0.000000e+000,0.000000e+000,2,9.538028e-001,1.825000e+000,,,,,,,,,,,,,,,,,,0,4.000000e+000,5.000000e-001,4,4,3.452778e-003,0,,0,
1564177957.918,,-1.800000e+003,4.003568e+000,1.741951e-005,2.199338e-007,0.000000e+000,0.000000e+000,2,9.569728e-001,1.825000e+000,,,,,,,,,,,,,,,,,,0,4.000000e+000,5.000000e-001,4,4,3.064156e-003,0,,0,
1564178100.938,,-1.700000e+003,4.001040e+000,1.655725e-005,2.256952e-007,0.000000e+000,0.000000e+000,2,9.573442e-001,1.825000e+000,,,,,,,,,,,,,,,,,,0,4.000000e+000,5.000000e-001,4,4,8.301020e-003,0,,0,
1564178235.238,,-1.600000e+003,4.001549e+000,1.531047e-005,1.172670e-007,0.000000e+000,0.000000e+000,2,9.527121e-001,1.825000e+000,,,,,,,,,,,,,,,,,,0,4.000000e+000,5.000000e-001,4,4,8.148909e-003,0,,0,
1564178398.648,,-1.500000e+003,4.002481e+000,1.444663e-005,1.437552e-007,0.000000e+000,0.000000e+000,2,9.535969e-001,1.825000e+000,,,,,,,,,,,,,,,,,,0,4.000000e+000,5.000000e-001,4,4,8.627176e-003,0,,0,
1564178540.669,,-1.400000e+003,4.001706e+000,1.352973e-005,1.047337e-007,0.000000e+000,0.000000e+000,2,9.327441e-001,1.825000e+000,,,,,,,,,,,,,,,,,,0,4.000000e+000,5.000000e-001,4,4,8.071899e-003,0,,0,
1564178694.959,,-1.300000e+003,4.001530e+000,1.250289e-005,1.041823e-007,0.000000e+000,0.000000e+000,2,9.503461e-001,1.825000e+000,,,,,,,,,,,,,,,,,,0,4.000000e+000,5.000000e-001,4,4,9.564877e-003,0,,0,
1564178834.229,,-1.200000e+003,4.001960e+000,1.133597e-005,2.226862e-007,0.000000e+000,0.000000e+000,2,9.141034e-001,1.825000e+000,,,,,,,,,,,,,,,,,,0,4.000000e+000,5.000000e-001,4,4,8.937120e-003,0,,0,
1564178973.189,,-1.100000e+003,4.001382e+000,1.014268e-005,1.256169e-007,0.000000e+000,0.000000e+000,2,9.385114e-001,1.825000e+000,,,,,,,,,,,,,,,,,,0,4.000000e+000,5.000000e-001,4,4,8.543253e-003,0,,0,
1564179124.799,,-1.000000e+003,4.002099e+000,9.256482e-006,5.887683e-008,0.000000e+000,0.000000e+000,2,9.289423e-001,1.825000e+000,,,,,,,,,,,,,,,,,,0,4.000000e+000,5.000000e-001,4,4,8.780241e-003,0,,0,
1564179266.770,,-9.000000e+002,4.001932e+000,8.370253e-006,1.935960e-007,0.000000e+000,0.000000e+000,2,8.951465e-001,1.825000e+000,,,,,,,,,,,,,,,,,,0,4.000000e+000,5.000000e-001,4,4,8.780718e-003,0,,0,
1564179401.820,,-8.000000e+002,4.001284e+000,7.170642e-006,9.856282e-008,0.000000e+000,0.000000e+000,2,9.223057e-001,1.825000e+000,,,,,,,,,,,,,,,,,,0,4.000000e+000,5.000000e-001,4,4,6.973028e-003,0,,0,
1564179540.430,,-7.000000e+002,4.001637e+000,6.036516e-006,1.329497e-007,0.000000e+000,0.000000e+000,2,9.411823e-001,1.825000e+000,,,,,,,,,,,,,,,,,,0,4.000000e+000,5.000000e-001,4,4,7.992983e-003,0,,0,
1564179682.700,,-6.000000e+002,4.001627e+000,4.970773e-006,1.691782e-007,0.000000e+000,0.000000e+000,2,8.922787e-001,1.825000e+000,,,,,,,,,,,,,,,,,,0,4.000000e+000,5.000000e-001,4,4,7.755995e-003,0,,0,
1564179817.470,,-5.000000e+002,4.002108e+000,4.205316e-006,1.647208e-007,0.000000e+000,0.000000e+000,2,8.851469e-001,1.825000e+000,,,,,,,,,,,,,,,,,,0,4.000000e+000,5.000000e-001,4,4,8.387327e-003,0,,0,
1564179982.001,,-4.500000e+002,4.002040e+000,3.523317e-006,1.807861e-007,0.000000e+000,0.000000e+000,2,9.066252e-001,1.825000e+000,,,,,,,,,,,,,,,,,,0,4.000000e+000,5.000000e-001,4,4,8.936167e-003,0,,0,
1564180149.351,,-4.000000e+002,4.003489e+000,2.521271e-006,1.243351e-006,0.000000e+000,0.000000e+000,2,6.501006e-001,1.825000e+000,,,,,,,,,,,,,,,,,,0,4.000000e+000,5.000000e-001,4,4,3.220081e-003,0,,0,
1564180321.451,,-3.500000e+002,4.002332e+000,2.575633e-006,1.502058e-007,0.000000e+000,0.000000e+000,2,8.956016e-001,1.825000e+000,,,,,,,,,,,,,,,,,,0,4.000000e+000,5.000000e-001,4,4,3.609180e-003,0,,0,
1564180485.491,,-3.000000e+002,4.003058e+000,2.139015e-006,1.231740e-007,0.000000e+000,0.000000e+000,2,8.134791e-001,1.825000e+000,,,,,,,,,,,,,,,,,,0,4.000000e+000,5.000000e-001,4,4,3.531933e-003,0,,0,
1564180622.261,,-2.500000e+002,4.000951e+000,1.472915e-006,1.694643e-007,0.000000e+000,0.000000e+000,2,7.932555e-001,1.825000e+000,,,,,,,,,,,,,,,,,,0,4.000000e+000,5.000000e-001,4,4,8.696795e-003,0,,0,
1564180766.522,,-2.000000e+002,4.002088e+000,1.079646e-006,1.938083e-007,0.000000e+000,0.000000e+000,2,6.079497e-001,1.825000e+000,,,,,,,,,,,,,,,,,,0,4.000000e+000,5.000000e-001,4,4,9.014845e-003,0,,0,
1564180926.342,,-1.500000e+002,4.002540e+000,5.254772e-007,1.021949e-007,0.000000e+000,0.000000e+000,2,5.230417e-001,1.825000e+000,,,,,,,,,,,,,,,,,,0,4.000000e+000,5.000000e-001,4,4,9.017944e-003,0,,0,
1564181070.852,,-1.000000e+002,4.002157e+000,8.959141e-008,8.726730e-008,0.000000e+000,0.000000e+000,2,4.967976e-002,1.825000e+000,,,,,,,,,,,,,,,,,,0,4.000000e+000,5.000000e-001,4,4,7.838011e-003,0,,0,
1564181207.112,,-5.000000e+001,4.001765e+000,-4.247106e-007,8.666989e-008,0.000000e+000,0.000000e+000,2,2.944983e-001,1.825000e+000,,,,,,,,,,,,,,,,,,0,4.000000e+000,5.000000e-001,4,4,8.621931e-003,0,,0,
1564181351.152,,0.000000e+000,4.001863e+000,-8.609151e-007,6.601942e-008,0.000000e+000,0.000000e+000,2,6.081378e-001,1.825000e+000,,,,,,,,,,,,,,,,,,0,4.000000e+000,5.000000e-001,4,4,8.305788e-003,0,,0,
1564181482.413,,5.000000e+001,4.001441e+000,-1.401076e-006,1.128981e-007,0.000000e+000,0.000000e+000,2,7.162418e-001,1.825000e+000,,,,,,,,,,,,,,,,,,0,4.000000e+000,5.000000e-001,4,4,9.324074e-003,0,,0,
1564181626.433,,1.000000e+002,4.001617e+000,-1.865236e-006,4.173092e-008,0.000000e+000,0.000000e+000,2,8.587731e-001,1.825000e+000,,,,,,,,,,,,,,,,,,0,4.000000e+000,5.000000e-001,4,4,8.702993e-003,0,,0,
1564181770.573,,1.500000e+002,4.001980e+000,-2.364431e-006,2.994225e-008,0.000000e+000,0.000000e+000,2,9.030129e-001,1.825000e+000,,,,,,,,,,,,,,,,,,0,4.000000e+000,5.000000e-001,4,4,7.365942e-003,0,,0,
1564181915.113,,2.000000e+002,4.001725e+000,-2.889064e-006,6.096064e-008,0.000000e+000,0.000000e+000,2,9.054363e-001,1.825000e+000,,,,,,,,,,,,,,,,,,0,4.000000e+000,5.000000e-001,4,4,8.387327e-003,0,,0,
1564182079.413,,2.500000e+002,4.002697e+000,-3.421012e-006,5.174352e-008,0.000000e+000,0.000000e+000,2,9.214656e-001,1.825000e+000,,,,,,,,,,,,,,,,,,0,4.000000e+000,5.000000e-001,4,4,8.232832e-003,0,,0,
1564182219.684,,3.000000e+002,4.001941e+000,-3.910437e-006,4.198906e-008,0.000000e+000,0.000000e+000,2,9.387042e-001,1.825000e+000,,,,,,,,,,,,,,,,,,0,4.000000e+000,5.000000e-001,4,4,7.999182e-003,0,,0,
1564182351.944,,3.500000e+002,4.002078e+000,-4.315122e-006,6.758781e-008,0.000000e+000,0.000000e+000,2,9.323424e-001,1.825000e+000,,,,,,,,,,,,,,,,,,0,4.000000e+000,5.000000e-001,4,4,6.895781e-003,0,,0,
1564182496.204,,4.000000e+002,4.001538e+000,-4.835078e-006,2.746030e-008,0.000000e+000,0.000000e+000,2,9.416540e-001,1.825000e+000,,,,,,,,,,,,,,,,,,0,4.000000e+000,5.000000e-001,4,4,8.857965e-003,0,,0,
1564182628.514,,4.500000e+002,4.001616e+000,-5.324493e-006,2.462590e-008,0.000000e+000,0.000000e+000,2,9.224100e-001,1.825000e+000,,,,,,,,,,,,,,,,,,0,4.000000e+000,5.000000e-001,4,4,7.130861e-003,0,,0,
1564182765.024,,5.000000e+002,4.001863e+000,-5.855065e-006,6.739846e-008,0.000000e+000,0.000000e+000,2,9.325765e-001,1.825000e+000,,,,,,,,,,,,,,,,,,0,4.000000e+000,5.000000e-001,4,4,8.468866e-003,0,,0,
1564182904.625,,6.000000e+002,4.002147e+000,-6.828980e-006,1.654383e-008,0.000000e+000,0.000000e+000,2,9.412943e-001,1.825000e+000,,,,,,,,,,,,,,,,,,0,4.000000e+000,5.000000e-001,4,4,8.548260e-003,0,,0,
1564183040.685,,7.000000e+002,4.002117e+000,-7.846902e-006,1.409006e-007,0.000000e+000,0.000000e+000,2,9.171521e-001,1.825000e+000,,,,,,,,,,,,,,,,,,0,4.000000e+000,5.000000e-001,4,4,6.975889e-003,0,,0,
1564183180.215,,8.000000e+002,4.002077e+000,-8.850080e-006,4.573657e-008,0.000000e+000,0.000000e+000,2,9.468865e-001,1.825000e+000,,,,,,,,,,,,,,,,,,0,4.000000e+000,5.000000e-001,4,4,7.524729e-003,0,,0,
1564183324.285,,9.000000e+002,4.003610e+000,-9.881804e-006,6.924813e-008,0.000000e+000,0.000000e+000,2,9.484016e-001,1.825000e+000,,,,,,,,,,,,,,,,,,0,4.000000e+000,5.000000e-001,4,4,8.157969e-003,0,,0,
1564183468.585,,1.000000e+003,4.002932e+000,-1.099870e-005,1.062073e-007,0.000000e+000,0.000000e+000,2,9.325498e-001,1.825000e+000,,,,,,,,,,,,,,,,,,0,4.000000e+000,5.000000e-001,4,4,8.080959e-003,0,,0,
1564183613.366,,1.100000e+003,4.003610e+000,-1.182768e-005,1.889630e-007,0.000000e+000,0.000000e+000,2,9.386991e-001,1.825000e+000,,,,,,,,,,,,,,,,,,0,4.000000e+000,5.000000e-001,4,4,8.079290e-003,0,,0,
1564183777.626,,1.200000e+003,4.003011e+000,-1.298951e-005,1.034302e-007,0.000000e+000,0.000000e+000,2,9.483254e-001,1.825000e+000,,,,,,,,,,,,,,,,,,0,4.000000e+000,5.000000e-001,4,4,8.394003e-003,0,,0,
1564183941.696,,1.300000e+003,4.004406e+000,-1.409980e-005,1.970153e-007,0.000000e+000,0.000000e+000,2,9.334002e-001,1.825000e+000,,,,,,,,,,,,,,,,,,0,4.000000e+000,5.000000e-001,4,4,8.869886e-003,0,,0,
1564184090.486,,1.400000e+003,4.004681e+000,-1.520947e-005,2.563811e-007,0.000000e+000,0.000000e+000,2,9.287152e-001,1.825000e+000,,,,,,,,,,,,,,,,,,0,4.000000e+000,5.000000e-001,4,4,9.818077e-003,0,,0,
1564184243.496,,1.500000e+003,4.004653e+000,-1.562816e-005,2.735566e-007,0.000000e+000,0.000000e+000,2,8.861431e-001,1.825000e+000,,,,,,,,,,,,,,,,,,0,4.000000e+000,5.000000e-001,4,4,1.115513e-002,0,,0,
1564184408.057,,1.600000e+003,4.004564e+000,-1.716144e-005,3.565222e-007,0.000000e+000,0.000000e+000,2,9.104927e-001,1.825000e+000,,,,,,,,,,,,,,,,,,0,4.000000e+000,5.000000e-001,4,4,1.012516e-002,0,,0,
1564184564.647,,1.700000e+003,4.005223e+000,-1.814750e-005,9.765177e-008,0.000000e+000,0.000000e+000,2,9.412509e-001,1.825000e+000,,,,,,,,,,,,,,,,,,0,4.000000e+000,5.000000e-001,4,4,1.177907e-002,0,,0,
1564184704.467,,1.800000e+003,4.005066e+000,-1.919412e-005,2.171117e-007,0.000000e+000,0.000000e+000,2,9.246703e-001,1.825000e+000,,,,,,,,,,,,,,,,,,0,4.000000e+000,5.000000e-001,4,4,1.130891e-002,0,,0,
1564184865.227,,2.000000e+003,4.004221e+000,-2.133341e-005,3.177405e-007,0.000000e+000,0.000000e+000,2,9.360401e-001,1.825000e+000,,,,,,,,,,,,,,,,,,0,4.000000e+000,5.000000e-001,4,4,1.334000e-002,0,,0,
1564185022.027,,3.000000e+003,4.005312e+000,-3.194579e-005,1.229615e-007,0.000000e+000,0.000000e+000,2,9.577798e-001,1.825000e+000,,,,,,,,,,,,,,,,,,0,4.000000e+000,5.000000e-001,4,4,1.224399e-002,0,,0,
1564185190.888,,4.000000e+003,4.005401e+000,-4.312257e-005,6.533813e-008,0.000000e+000,0.000000e+000,2,9.580580e-001,1.825000e+000,,,,,,,,,,,,,,,,,,0,4.000000e+000,5.000000e-001,4,4,1.216722e-002,0,,0,
1564185351.658,,5.000000e+003,4.004319e+000,-5.401832e-005,3.225041e-008,0.000000e+000,0.000000e+000,2,9.564846e-001,1.825000e+000,,,,,,,,,,,,,,,,,,0,4.000000e+000,5.000000e-001,4,4,1.192522e-002,0,,0,
1564185496.708,,7.500000e+003,4.003975e+000,-8.232571e-005,2.006945e-007,0.000000e+000,0.000000e+000,2,9.569573e-001,1.825000e+000,,,,,,,,,,,,,,,,,,0,4.000000e+000,5.000000e-001,4,4,1.059008e-002,0,,0,
1564185641.978,,1.000000e+004,4.003818e+000,-1.108133e-004,2.938794e-007,0.000000e+000,0.000000e+000,2,9.598455e-001,1.825000e+000,,,,,,,,,,,,,,,,,,0,4.000000e+000,5.000000e-001,4,4,1.216722e-002,0,,0,
1564185798.959,,1.500000e+004,4.004045e+000,-1.680258e-004,3.994467e-007,0.000000e+000,0.000000e+000,2,9.580586e-001,1.825000e+000,,,,,,,,,,,,,,,,,,0,4.000000e+000,5.000000e-001,4,4,1.318789e-002,0,,0,
1564185965.329,,2.000000e+004,4.004487e+000,-2.250911e-004,6.786362e-007,0.000000e+000,0.000000e+000,2,9.599929e-001,1.825000e+000,,,,,,,,,,,,,,,,,,0,4.000000e+000,5.000000e-001,4,4,1.319003e-002,0,,0,
1564186118.129,,2.500000e+004,4.003031e+000,-2.820129e-004,8.607411e-007,0.000000e+000,0.000000e+000,2,9.594142e-001,1.825000e+000,,,,,,,,,,,,,,,,,,0,4.000000e+000,5.000000e-001,4,4,8.939266e-003,0,,0,
1564186273.159,,3.000000e+004,4.004063e+000,-3.403125e-004,8.435030e-007,0.000000e+000,0.000000e+000,2,9.640687e-001,1.825000e+000,,,,,,,,,,,,,,,,,,0,4.000000e+000,5.000000e-001,4,4,1.083112e-002,0,,0,
1564186424.199,,3.500000e+004,4.003582e+000,-3.982515e-004,9.290032e-007,0.000000e+000,0.000000e+000,2,9.619992e-001,1.825000e+000,,,,,,,,,,,,,,,,,,0,4.000000e+000,5.000000e-001,4,4,9.175062e-003,0,,0,
1564186584.560,,4.000000e+004,4.003895e+000,-4.550974e-004,1.087205e-006,0.000000e+000,0.000000e+000,2,9.625586e-001,1.825000e+000,,,,,,,,,,,,,,,,,,0,4.000000e+000,5.000000e-001,4,4,9.258032e-003,0,,0,
1564186746.590,,4.500000e+004,4.003748e+000,-5.130392e-004,6.568048e-007,0.000000e+000,0.000000e+000,2,9.650932e-001,1.825000e+000,,,,,,,,,,,,,,,,,,0,4.000000e+000,5.000000e-001,4,4,9.496212e-003,0,,0,
1564186905.570,,5.000000e+004,4.003325e+000,-5.710665e-004,9.119818e-007,0.000000e+000,0.000000e+000,2,9.650048e-001,1.825000e+000,,,,,,,,,,,,,,,,,,0,4.000000e+000,5.000000e-001,4,4,8.079052e-003,0,,0,