File: examples/squid/data/Reference_C21_1_1906_HipII110_[L]_CSH_50,0mg_+b13,7mg_m(T,5kOe,FC)_300K_to_4K_14062019.rso.dat
[Header]
TITLE,MPMS RSO Measurement
BYAPP,MPMS Measurement,1.1,Summary
FILEOPENTIME, 1560544929.827000 6/14/2019, 10:42:09 PM

INFO, APPNAME, MPMS MultiVu Application, Revision 1.61,  Build 082

INFO, NAME, Reference_C21_1_1906_HipII110_[L]_50.0mg+b13.7mg
INFO, WEIGHT, 63.700
INFO, AREA, 20.000
INFO, LENGTH, 0.000
INFO, SHAPE, 0
INFO, COMMENT, Hip II 110
INFO, SEQUENCE FILE: FC_5kOe_300_to_4_sweep.seq


INFO, BACKGROUND DATA FILE:, None


STARTUPAXIS,X,4,LINEAR,AUTO,0.000000,0.000000
STARTUPAXIS,Y1,5,LINEAR,AUTO,0.000000,0.000000


STARTUPGROUP,Longitudinal
FIELDGROUP,Longitudinal,1,2,3,4,5,6,7,8,9,10,11,19,20,21,22,23,35
FIELDGROUP,Transverse,1,2,3,4,12,13,14,15,16,17,18,24,25,26,27,28,35

PLOT_APPEARANCE,ALL,HORZ_GRID_ON,VERT_GRID_ON,MARKERS_AND_LINES

[Data]
Time,Comment,Field (Oe),Temperature (K),Long Moment (emu),Long Scan Std Dev,Long Offset (cm),Long Offset Std Dev,Long Algorithm,Long Reg Fit,Long Reg Factor,Trans Moment (emu),Trans Scan Std Dev,Trans Offset (cm),Trans Offset Std Dev,Trans Algorithm,Trans Reg Fit,Trans Reg Factor,Long Moment [w/o ABS] (emu),Long Scan Std Dev [w/o ABS],Long Offset [w/o ABS] (cm),Long Offset Std Dev [w/o ABS],Long Reg Fit [w/o ABS],Trans Moment [w/o ABS] (emu),Trans Scan Std Dev [w/o ABS],Trans Offset [w/o ABS] (cm),Trans Offset Std Dev [w/o ABS],Trans Reg Fit [w/o ABS],RSO Position (deg),Amplitude (cm),Frequency,Cycles to Average,Scans per Measurement,Delta Temp (K),Error,EC Comp. Running,Using ABS,
1560544929.827,,5.000000e+003,3.000163e+002,-2.053516e-006,3.642666e-007,0.000000e+000,0.000000e+000,2,0.000000e+000,1.825000e+000,,,,,,,,,,,,,,,,,,0,4.000000e+000,1.000000e+000,3,8,2.258301e-002,0,,0,
1560545076.708,,5.000000e+003,2.966666e+002,-2.297774e-006,1.908337e-007,0.000000e+000,0.000000e+000,2,0.000000e+000,1.825000e+000,,,,,,,,,,,,,,,,,,0,4.000000e+000,1.000000e+000,3,8,2.925201e+000,0,,0,
1560545140.038,,5.000000e+003,2.929725e+002,-2.235973e-006,1.565873e-007,0.000000e+000,0.000000e+000,2,0.000000e+000,1.825000e+000,,,,,,,,,,,,,,,,,,0,4.000000e+000,1.000000e+000,3,8,3.823395e+000,0,,0,
1560545204.188,,5.000000e+003,2.892092e+002,-2.219063e-006,2.470767e-007,0.000000e+000,0.000000e+000,2,0.000000e+000,1.825000e+000,,,,,,,,,,,,,,,,,,0,4.000000e+000,1.000000e+000,3,8,3.308899e+000,0,,0,
1560545267.578,,5.000000e+003,2.863618e+002,-2.238687e-006,3.262853e-007,0.000000e+000,0.000000e+000,2,0.000000e+000,1.825000e+000,,,,,,,,,,,,,,,,,,0,4.000000e+000,1.000000e+000,3,8,2.146912e+000,0,,0,
1560545332.008,,5.000000e+003,2.846035e+002,-2.262133e-006,3.605680e-007,0.000000e+000,0.000000e+000,2,0.000000e+000,1.825000e+000,,,,,,,,,,,,,,,,,,0,4.000000e+000,1.000000e+000,3,8,1.251617e+000,0,,0,
1560545394.698,,5.000000e+003,2.835212e+002,-2.213778e-006,2.422944e-007,0.000000e+000,0.000000e+000,2,0.000000e+000,1.825000e+000,,,,,,,,,,,,,,,,,,0,4.000000e+000,1.000000e+000,3,8,1.000793e+000,0,,0,
1560545458.958,,5.000000e+003,2.822663e+002,-2.165237e-006,1.571102e-007,0.000000e+000,0.000000e+000,2,0.000000e+000,1.825000e+000,,,,,,,,,,,,,,,,,,0,4.000000e+000,1.000000e+000,3,8,1.477112e+000,0,,0,
1560545522.038,,5.000000e+003,2.805000e+002,-2.291156e-006,3.237684e-007,0.000000e+000,0.000000e+000,2,0.000000e+000,1.825000e+000,,,,,,,,,,,,,,,,,,0,4.000000e+000,1.000000e+000,3,8,1.967010e+000,0,,0,
1560545585.828,,5.000000e+003,2.783718e+002,-2.115506e-006,2.071383e-007,0.000000e+000,0.000000e+000,2,0.000000e+000,1.825000e+000,,,,,,,,,,,,,,,,,,0,4.000000e+000,1.000000e+000,3,8,2.129517e+000,0,,0,
1560545649.278,,5.000000e+003,2.762050e+002,-1.756368e-006,1.929065e-007,0.000000e+000,0.000000e+000,2,0.000000e+000,1.825000e+000,,,,,,,,,,,,,,,,,,0,4.000000e+000,1.000000e+000,3,8,2.009308e+000,0,,0,
1560545714.378,,5.000000e+003,2.740831e+002,-2.143858e-006,2.897256e-007,0.000000e+000,0.000000e+000,2,0.000000e+000,1.825000e+000,,,,,,,,,,,,,,,,,,0,4.000000e+000,1.000000e+000,3,8,2.023590e+000,0,,0,
1560545779.068,,5.000000e+003,2.719929e+002,-1.942432e-006,3.696730e-007,0.000000e+000,0.000000e+000,2,0.000000e+000,1.825000e+000,,,,,,,,,,,,,,,,,,0,4.000000e+000,1.000000e+000,3,8,1.963684e+000,0,,0,
1560545843.719,,5.000000e+003,2.699199e+002,-2.158193e-006,2.899144e-007,0.000000e+000,0.000000e+000,2,0.000000e+000,1.825000e+000,,,,,,,,,,,,,,,,,,0,4.000000e+000,1.000000e+000,3,8,1.978088e+000,0,,0,
1560545908.319,,5.000000e+003,2.679094e+002,-2.133489e-006,2.061622e-007,0.000000e+000,0.000000e+000,2,0.000000e+000,1.825000e+000,,,,,,,,,,,,,,,,,,0,4.000000e+000,1.000000e+000,3,8,1.973602e+000,0,,0,
1560545971.719,,5.000000e+003,2.658902e+002,-2.096863e-006,3.474630e-007,0.000000e+000,0.000000e+000,2,0.000000e+000,1.825000e+000,,,,,,,,,,,,,,,,,,0,4.000000e+000,1.000000e+000,3,8,1.916321e+000,0,,0,
1560546034.159,,5.000000e+003,2.639282e+002,-1.894853e-006,1.874969e-007,0.000000e+000,0.000000e+000,2,0.000000e+000,1.825000e+000,,,,,,,,,,,,,,,,,,0,4.000000e+000,1.000000e+000,3,8,1.869598e+000,0,,0,
1560546097.359,,5.000000e+003,2.619818e+002,-1.857485e-006,2.762121e-007,0.000000e+000,0.000000e+000,2,0.000000e+000,1.825000e+000,,,,,,,,,,,,,,,,,,0,4.000000e+000,1.000000e+000,3,8,1.959320e+000,0,,0,
1560546160.819,,5.000000e+003,2.599322e+002,-1.914741e-006,3.856548e-007,0.000000e+000,0.000000e+000,2,0.000000e+000,1.825000e+000,,,,,,,,,,,,,,,,,,0,4.000000e+000,1.000000e+000,3,8,1.954987e+000,0,,0,
1560546224.999,,5.000000e+003,2.577985e+002,-1.982104e-006,2.753258e-007,0.000000e+000,0.000000e+000,2,0.000000e+000,1.825000e+000,,,,,,,,,,,,,,,,,,0,4.000000e+000,1.000000e+000,3,8,2.031281e+000,0,,0,
1560546288.399,,5.000000e+003,2.556917e+002,-2.029505e-006,2.794894e-007,0.000000e+000,0.000000e+000,2,0.000000e+000,1.825000e+000,,,,,,,,,,,,,,,,,,0,4.000000e+000,1.000000e+000,3,8,1.999298e+000,0,,0,
1560546351.899,,5.000000e+003,2.536017e+002,-2.046366e-006,4.506981e-007,0.000000e+000,0.000000e+000,2,1.189347e-002,1.825000e+000,,,,,,,,,,,,,,,,,,0,4.000000e+000,1.000000e+000,3,8,2.000198e+000,0,,0,
1560546415.469,,5.000000e+003,2.515257e+002,-2.018266e-006,2.219778e-007,0.000000e+000,0.000000e+000,2,0.000000e+000,1.825000e+000,,,,,,,,,,,,,,,,,,0,4.000000e+000,1.000000e+000,3,8,1.999710e+000,0,,0,
1560546478.549,,5.000000e+003,2.494590e+002,-1.948886e-006,1.805986e-007,0.000000e+000,0.000000e+000,2,0.000000e+000,1.825000e+000,,,,,,,,,,,,,,,,,,0,4.000000e+000,1.000000e+000,3,8,1.937302e+000,0,,0,
1560546541.760,,5.000000e+003,2.474099e+002,-1.938837e-006,1.556679e-007,0.000000e+000,0.000000e+000,2,0.000000e+000,1.825000e+000,,,,,,,,,,,,,,,,,,0,4.000000e+000,1.000000e+000,3,8,1.967712e+000,0,,0,
1560546605.710,,5.000000e+003,2.453552e+002,-1.990546e-006,2.212312e-007,0.000000e+000,0.000000e+000,2,0.000000e+000,1.825000e+000,,,,,,,,,,,,,,,,,,0,4.000000e+000,1.000000e+000,3,8,1.974213e+000,0,,0,
1560546669.610,,5.000000e+003,2.433105e+002,-1.963316e-006,3.048006e-007,0.000000e+000,0.000000e+000,2,0.000000e+000,1.825000e+000,,,,,,,,,,,,,,,,,,0,4.000000e+000,1.000000e+000,3,8,1.949799e+000,0,,0,
1560546733.240,,5.000000e+003,2.412455e+002,-2.029369e-006,2.309843e-007,0.000000e+000,0.000000e+000,2,0.000000e+000,1.825000e+000,,,,,,,,,,,,,,,,,,0,4.000000e+000,1.000000e+000,3,8,1.997910e+000,0,,0,
1560546797.170,,5.000000e+003,2.391893e+002,-1.927872e-006,3.565322e-007,0.000000e+000,0.000000e+000,2,0.000000e+000,1.825000e+000,,,,,,,,,,,,,,,,,,0,4.000000e+000,1.000000e+000,3,8,2.014801e+000,0,,0,
1560546860.840,,5.000000e+003,2.371134e+002,-1.904276e-006,2.968187e-007,0.000000e+000,0.000000e+000,2,0.000000e+000,1.825000e+000,,,,,,,,,,,,,,,,,,0,4.000000e+000,1.000000e+000,3,8,2.016296e+000,0,,0,
1560546925.300,,5.000000e+003,2.350206e+002,-1.932273e-006,2.644731e-007,0.000000e+000,0.000000e+000,2,0.000000e+000,1.825000e+000,,,,,,,,,,,,,,,,,,0,4.000000e+000,1.000000e+000,3,8,2.016510e+000,0,,0,
1560546989.210,,5.000000e+003,2.329266e+002,-1.957886e-006,3.403920e-007,0.000000e+000,0.000000e+000,2,0.000000e+000,1.825000e+000,,,,,,,,,,,,,,,,,,0,4.000000e+000,1.000000e+000,3,8,2.007095e+000,0,,0,
1560547051.390,,5.000000e+003,2.308563e+002,-2.089900e-006,2.727034e-007,0.000000e+000,0.000000e+000,2,0.000000e+000,1.825000e+000,,,,,,,,,,,,,,,,,,0,4.000000e+000,1.000000e+000,3,8,1.934998e+000,0,,0,
1560547115.060,,5.000000e+003,2.287954e+002,-2.043865e-006,2.657879e-007,0.000000e+000,0.000000e+000,2,0.000000e+000,1.825000e+000,,,,,,,,,,,,,,,,,,0,4.000000e+000,1.000000e+000,3,8,2.006805e+000,0,,0,
1560547179.010,,5.000000e+003,2.267340e+002,-1.940130e-006,3.597220e-007,0.000000e+000,0.000000e+000,2,0.000000e+000,1.825000e+000,,,,,,,,,,,,,,,,,,0,4.000000e+000,1.000000e+000,3,8,1.997696e+000,0,,0,
1560547242.681,,5.000000e+003,2.246725e+002,-1.753827e-006,3.059300e-007,0.000000e+000,0.000000e+000,2,0.000000e+000,1.825000e+000,,,,,,,,,,,,,,,,,,0,4.000000e+000,1.000000e+000,3,8,1.943604e+000,0,,0,
1560547306.801,,5.000000e+003,2.226274e+002,-1.872419e-006,2.132407e-007,0.000000e+000,0.000000e+000,2,0.000000e+000,1.825000e+000,,,,,,,,,,,,,,,,,,0,4.000000e+000,1.000000e+000,3,8,1.941208e+000,0,,0,
1560547371.021,,5.000000e+003,2.206014e+002,-1.941017e-006,3.064538e-007,0.000000e+000,0.000000e+000,2,0.000000e+000,1.825000e+000,,,,,,,,,,,,,,,,,,0,4.000000e+000,1.000000e+000,3,8,1.974503e+000,0,,0,
1560547432.891,,5.000000e+003,2.186123e+002,-1.872959e-006,2.457274e-007,0.000000e+000,0.000000e+000,2,0.000000e+000,1.825000e+000,,,,,,,,,,,,,,,,,,0,4.000000e+000,1.000000e+000,3,8,1.934708e+000,0,,0,
1560547497.061,,5.000000e+003,2.165943e+002,-1.789229e-006,4.897165e-007,0.000000e+000,0.000000e+000,2,0.000000e+000,1.825000e+000,,,,,,,,,,,,,,,,,,0,4.000000e+000,1.000000e+000,3,8,2.006210e+000,0,,0,
1560547560.761,,5.000000e+003,2.144848e+002,-1.791177e-006,2.879360e-007,0.000000e+000,0.000000e+000,2,0.000000e+000,1.825000e+000,,,,,,,,,,,,,,,,,,0,4.000000e+000,1.000000e+000,3,8,1.991898e+000,0,,0,
1560547623.421,,5.000000e+003,2.124287e+002,-1.718159e-006,2.495574e-007,0.000000e+000,0.000000e+000,2,0.000000e+000,1.825000e+000,,,,,,,,,,,,,,,,,,0,4.000000e+000,1.000000e+000,3,8,1.949997e+000,0,,0,
1560547686.661,,5.000000e+003,2.103689e+002,-1.797720e-006,4.815291e-007,0.000000e+000,0.000000e+000,2,0.000000e+000,1.825000e+000,,,,,,,,,,,,,,,,,,0,4.000000e+000,1.000000e+000,3,8,1.991898e+000,0,,0,
1560547748.831,,5.000000e+003,2.083183e+002,-1.894934e-006,3.302511e-007,0.000000e+000,0.000000e+000,2,0.000000e+000,1.825000e+000,,,,,,,,,,,,,,,,,,0,4.000000e+000,1.000000e+000,3,8,1.976196e+000,0,,0,
1560547810.071,,5.000000e+003,2.063606e+002,-1.715273e-006,2.114501e-007,0.000000e+000,0.000000e+000,2,0.000000e+000,1.825000e+000,,,,,,,,,,,,,,,,,,0,4.000000e+000,1.000000e+000,3,8,1.940796e+000,0,,0,
1560547873.371,,5.000000e+003,2.043656e+002,-1.903681e-006,3.880356e-007,0.000000e+000,0.000000e+000,2,0.000000e+000,1.825000e+000,,,,,,,,,,,,,,,,,,0,4.000000e+000,1.000000e+000,3,8,1.899689e+000,0,,0,
1560547935.781,,5.000000e+003,2.024218e+002,-1.782529e-006,4.067167e-007,0.000000e+000,0.000000e+000,2,0.000000e+000,1.825000e+000,,,,,,,,,,,,,,,,,,0,4.000000e+000,1.000000e+000,3,8,1.932602e+000,0,,0,
1560547998.672,,5.000000e+003,2.004353e+002,-1.799526e-006,3.043500e-007,0.000000e+000,0.000000e+000,2,0.000000e+000,1.825000e+000,,,,,,,,,,,,,,,,,,0,4.000000e+000,1.000000e+000,3,8,1.856506e+000,0,,0,
1560548060.582,,5.000000e+003,1.985076e+002,-1.826451e-006,2.803033e-007,0.000000e+000,0.000000e+000,2,0.000000e+000,1.825000e+000,,,,,,,,,,,,,,,,,,0,4.000000e+000,1.000000e+000,3,8,1.912399e+000,0,,0,
1560548124.212,,5.000000e+003,1.965087e+002,-1.607304e-006,2.627058e-007,0.000000e+000,0.000000e+000,2,0.000000e+000,1.825000e+000,,,,,,,,,,,,,,,,,,0,4.000000e+000,1.000000e+000,3,8,1.959106e+000,0,,0,
1560548187.592,,5.000000e+003,1.944595e+002,-1.800925e-006,3.090597e-007,0.000000e+000,0.000000e+000,2,0.000000e+000,1.825000e+000,,,,,,,,,,,,,,,,,,0,4.000000e+000,1.000000e+000,3,8,1.959106e+000,0,,0,
1560548250.232,,5.000000e+003,1.924117e+002,-1.753619e-006,2.495155e-007,0.000000e+000,0.000000e+000,2,0.000000e+000,1.825000e+000,,,,,,,,,,,,,,,,,,0,4.000000e+000,1.000000e+000,3,8,1.981201e+000,0,,0,
1560548314.262,,5.000000e+003,1.903241e+002,-1.646196e-006,3.828784e-007,0.000000e+000,0.000000e+000,2,0.000000e+000,1.825000e+000,,,,,,,,,,,,,,,,,,0,4.000000e+000,1.000000e+000,3,8,2.064606e+000,0,,0,
1560548377.862,,5.000000e+003,1.882372e+002,-1.694978e-006,2.361898e-007,0.000000e+000,0.000000e+000,2,0.000000e+000,1.825000e+000,,,,,,,,,,,,,,,,,,0,4.000000e+000,1.000000e+000,3,8,2.017807e+000,0,,0,
1560548442.032,,5.000000e+003,1.861402e+002,-1.616121e-006,2.114116e-007,0.000000e+000,0.000000e+000,2,0.000000e+000,1.825000e+000,,,,,,,,,,,,,,,,,,0,4.000000e+000,1.000000e+000,3,8,2.019592e+000,0,,0,
1560548505.662,,5.000000e+003,1.840692e+002,-1.725153e-006,4.146142e-007,0.000000e+000,0.000000e+000,2,0.000000e+000,1.825000e+000,,,,,,,,,,,,,,,,,,0,4.000000e+000,1.000000e+000,3,8,1.968903e+000,0,,0,
1560548569.262,,5.000000e+003,1.820388e+002,-1.735741e-006,3.590042e-007,0.000000e+000,0.000000e+000,2,0.000000e+000,1.825000e+000,,,,,,,,,,,,,,,,,,0,4.000000e+000,1.000000e+000,3,8,1.970901e+000,0,,0,
1560548632.452,,5.000000e+003,1.800300e+002,-1.691927e-006,3.023790e-007,0.000000e+000,0.000000e+000,2,0.000000e+000,1.825000e+000,,,,,,,,,,,,,,,,,,0,4.000000e+000,1.000000e+000,3,8,1.992294e+000,0,,0,
1560548695.883,,5.000000e+003,1.779676e+002,-1.782696e-006,2.239832e-007,0.000000e+000,0.000000e+000,2,0.000000e+000,1.825000e+000,,,,,,,,,,,,,,,,,,0,4.000000e+000,1.000000e+000,3,8,1.946198e+000,0,,0,
1560548759.573,,5.000000e+003,1.758818e+002,-1.570619e-006,3.899573e-007,0.000000e+000,0.000000e+000,2,0.000000e+000,1.825000e+000,,,,,,,,,,,,,,,,,,0,4.000000e+000,1.000000e+000,3,8,2.011688e+000,0,,0,
1560548822.423,,5.000000e+003,1.738232e+002,-1.697880e-006,2.563109e-007,0.000000e+000,0.000000e+000,2,0.000000e+000,1.825000e+000,,,,,,,,,,,,,,,,,,0,4.000000e+000,1.000000e+000,3,8,1.968704e+000,0,,0,
1560548884.883,,5.000000e+003,1.717617e+002,-1.547932e-006,3.310147e-007,0.000000e+000,0.000000e+000,2,0.000000e+000,1.825000e+000,,,,,,,,,,,,,,,,,,0,4.000000e+000,1.000000e+000,3,8,1.963791e+000,0,,0,
1560548948.553,,5.000000e+003,1.697002e+002,-1.758711e-006,2.847376e-007,0.000000e+000,0.000000e+000,2,0.000000e+000,1.825000e+000,,,,,,,,,,,,,,,,,,0,4.000000e+000,1.000000e+000,3,8,1.980499e+000,0,,0,
1560549011.393,,5.000000e+003,1.676348e+002,-1.739651e-006,1.862068e-007,0.000000e+000,0.000000e+000,2,0.000000e+000,1.825000e+000,,,,,,,,,,,,,,,,,,0,4.000000e+000,1.000000e+000,3,8,1.943695e+000,0,,0,
1560549075.013,,5.000000e+003,1.655780e+002,-1.483974e-006,2.899587e-007,0.000000e+000,0.000000e+000,2,0.000000e+000,1.825000e+000,,,,,,,,,,,,,,,,,,0,4.000000e+000,1.000000e+000,3,8,1.925201e+000,0,,0,
1560549138.433,,5.000000e+003,1.635307e+002,-1.824717e-006,3.243458e-007,0.000000e+000,0.000000e+000,2,0.000000e+000,1.825000e+000,,,,,,,,,,,,,,,,,,0,4.000000e+000,1.000000e+000,3,8,1.923904e+000,0,,0,
1560549200.123,,5.000000e+003,1.615616e+002,-1.492759e-006,3.905358e-007,0.000000e+000,0.000000e+000,2,0.000000e+000,1.825000e+000,,,,,,,,,,,,,,,,,,0,4.000000e+000,1.000000e+000,3,8,1.957886e+000,0,,0,
1560549263.723,,5.000000e+003,1.595486e+002,-1.649483e-006,2.959679e-007,0.000000e+000,0.000000e+000,2,0.000000e+000,1.825000e+000,,,,,,,,,,,,,,,,,,0,4.000000e+000,1.000000e+000,3,8,1.931793e+000,0,,0,
1560549326.573,,5.000000e+003,1.575295e+002,-1.402664e-006,4.433255e-007,0.000000e+000,0.000000e+000,2,0.000000e+000,1.825000e+000,,,,,,,,,,,,,,,,,,0,4.000000e+000,1.000000e+000,3,8,1.940002e+000,0,,0,
1560549387.713,,5.000000e+003,1.555676e+002,-1.551559e-006,4.150209e-007,0.000000e+000,0.000000e+000,2,0.000000e+000,1.825000e+000,,,,,,,,,,,,,,,,,,0,4.000000e+000,1.000000e+000,3,8,1.886200e+000,0,,0,
1560549450.584,,5.000000e+003,1.535298e+002,-1.398582e-006,2.699992e-007,0.000000e+000,0.000000e+000,2,0.000000e+000,1.825000e+000,,,,,,,,,,,,,,,,,,0,4.000000e+000,1.000000e+000,3,8,1.925400e+000,0,,0,
1560549512.664,,5.000000e+003,1.514761e+002,-1.630074e-006,3.440736e-007,0.000000e+000,0.000000e+000,2,0.000000e+000,1.825000e+000,,,,,,,,,,,,,,,,,,0,4.000000e+000,1.000000e+000,3,8,1.948502e+000,0,,0,
1560549574.764,,5.000000e+003,1.494421e+002,-1.660487e-006,1.177826e-007,0.000000e+000,0.000000e+000,2,0.000000e+000,1.825000e+000,,,,,,,,,,,,,,,,,,0,4.000000e+000,1.000000e+000,3,8,1.966202e+000,0,,0,
1560549638.364,,5.000000e+003,1.473497e+002,-1.645147e-006,2.734617e-007,0.000000e+000,0.000000e+000,2,0.000000e+000,1.825000e+000,,,,,,,,,,,,,,,,,,0,4.000000e+000,1.000000e+000,3,8,1.968491e+000,0,,0,
1560549700.554,,5.000000e+003,1.452978e+002,-1.481095e-006,2.428949e-007,0.000000e+000,0.000000e+000,2,0.000000e+000,1.825000e+000,,,,,,,,,,,,,,,,,,0,4.000000e+000,1.000000e+000,3,8,1.941101e+000,0,,0,
1560549763.704,,5.000000e+003,1.432304e+002,-1.489865e-006,2.540756e-007,0.000000e+000,0.000000e+000,2,0.000000e+000,1.825000e+000,,,,,,,,,,,,,,,,,,0,4.000000e+000,1.000000e+000,3,8,2.010101e+000,0,,0,
1560549825.914,,5.000000e+003,1.412025e+002,-1.458176e-006,3.407312e-007,0.000000e+000,0.000000e+000,2,0.000000e+000,1.825000e+000,,,,,,,,,,,,,,,,,,0,4.000000e+000,1.000000e+000,3,8,1.953400e+000,0,,0,
1560549887.364,,5.000000e+003,1.392238e+002,-1.524288e-006,2.978968e-007,0.000000e+000,0.000000e+000,2,0.000000e+000,1.825000e+000,,,,,,,,,,,,,,,,,,0,4.000000e+000,1.000000e+000,3,8,1.904007e+000,0,,0,
1560549950.104,,5.000000e+003,1.372057e+002,-1.466646e-006,3.016093e-007,0.000000e+000,0.000000e+000,2,0.000000e+000,1.825000e+000,,,,,,,,,,,,,,,,,,0,4.000000e+000,1.000000e+000,3,8,1.946396e+000,0,,0,
1560550012.524,,5.000000e+003,1.352064e+002,-1.288241e-006,2.101597e-007,0.000000e+000,0.000000e+000,2,0.000000e+000,1.825000e+000,,,,,,,,,,,,,,,,,,0,4.000000e+000,1.000000e+000,3,8,1.915604e+000,0,,0,
1560550075.004,,5.000000e+003,1.331822e+002,-1.549502e-006,1.858650e-007,0.000000e+000,0.000000e+000,2,0.000000e+000,1.825000e+000,,,,,,,,,,,,,,,,,,0,4.000000e+000,1.000000e+000,3,8,1.956192e+000,0,,0,
1560550139.144,,5.000000e+003,1.310936e+002,-1.516794e-006,3.217386e-007,0.000000e+000,0.000000e+000,2,0.000000e+000,1.825000e+000,,,,,,,,,,,,,,,,,,0,4.000000e+000,1.000000e+000,3,8,1.995407e+000,0,,0,
1560550201.035,,5.000000e+003,1.290286e+002,-1.573914e-006,3.055110e-007,0.000000e+000,0.000000e+000,2,0.000000e+000,1.825000e+000,,,,,,,,,,,,,,,,,,0,4.000000e+000,1.000000e+000,3,8,1.961899e+000,0,,0,
1560550262.955,,5.000000e+003,1.269678e+002,-1.408542e-006,1.617377e-007,0.000000e+000,0.000000e+000,2,0.000000e+000,1.825000e+000,,,,,,,,,,,,,,,,,,0,4.000000e+000,1.000000e+000,3,8,1.998604e+000,0,,0,
1560550325.235,,5.000000e+003,1.248909e+002,-1.505631e-006,3.025487e-007,0.000000e+000,0.000000e+000,2,0.000000e+000,1.825000e+000,,,,,,,,,,,,,,,,,,0,4.000000e+000,1.000000e+000,3,8,1.991302e+000,0,,0,
1560550388.185,,5.000000e+003,1.228424e+002,-1.325910e-006,3.618489e-007,0.000000e+000,0.000000e+000,2,0.000000e+000,1.825000e+000,,,,,,,,,,,,,,,,,,0,4.000000e+000,1.000000e+000,3,8,1.968597e+000,0,,0,
1560550451.065,,5.000000e+003,1.207974e+002,-1.264714e-006,1.413297e-007,0.000000e+000,0.000000e+000,2,0.000000e+000,1.825000e+000,,,,,,,,,,,,,,,,,,0,4.000000e+000,1.000000e+000,3,8,1.964897e+000,0,,0,
1560550513.965,,5.000000e+003,1.187636e+002,-1.294967e-006,2.829148e-007,0.000000e+000,0.000000e+000,2,0.000000e+000,1.825000e+000,,,,,,,,,,,,,,,,,,0,4.000000e+000,1.000000e+000,3,8,1.939499e+000,0,,0,
1560550576.345,,5.000000e+003,1.167325e+002,-1.279360e-006,2.586340e-007,0.000000e+000,0.000000e+000,2,0.000000e+000,1.825000e+000,,,,,,,,,,,,,,,,,,0,4.000000e+000,1.000000e+000,3,8,1.897903e+000,0,,0,
1560550638.415,,5.000000e+003,1.147583e+002,-1.372205e-006,2.423359e-007,0.000000e+000,0.000000e+000,2,0.000000e+000,1.825000e+000,,,,,,,,,,,,,,,,,,0,4.000000e+000,1.000000e+000,3,8,1.908905e+000,0,,0,
1560550700.115,,5.000000e+003,1.127642e+002,-1.349120e-006,3.466377e-007,0.000000e+000,0.000000e+000,2,0.000000e+000,1.825000e+000,,,,,,,,,,,,,,,,,,0,4.000000e+000,1.000000e+000,3,8,1.925995e+000,0,,0,
1560550761.865,,5.000000e+003,1.107361e+002,-1.352312e-006,1.313020e-007,0.000000e+000,0.000000e+000,2,0.000000e+000,1.825000e+000,,,,,,,,,,,,,,,,,,0,4.000000e+000,1.000000e+000,3,8,2.003799e+000,0,,0,
1560550823.505,,5.000000e+003,1.086929e+002,-1.340911e-006,3.319878e-007,0.000000e+000,0.000000e+000,2,0.000000e+000,1.825000e+000,,,,,,,,,,,,,,,,,,0,4.000000e+000,1.000000e+000,3,8,1.995705e+000,0,,0,
1560550887.306,,5.000000e+003,1.065609e+002,-1.226845e-006,9.242586e-008,0.000000e+000,0.000000e+000,2,0.000000e+000,1.825000e+000,,,,,,,,,,,,,,,,,,0,4.000000e+000,1.000000e+000,3,8,2.062302e+000,0,,0,
1560550950.086,,5.000000e+003,1.044429e+002,-1.288848e-006,3.588978e-007,0.000000e+000,0.000000e+000,2,0.000000e+000,1.825000e+000,,,,,,,,,,,,,,,,,,0,4.000000e+000,1.000000e+000,3,8,1.985802e+000,0,,0,
1560551011.976,,5.000000e+003,1.023828e+002,-1.505714e-006,1.869977e-007,0.000000e+000,0.000000e+000,2,0.000000e+000,1.825000e+000,,,,,,,,,,,,,,,,,,0,4.000000e+000,1.000000e+000,3,8,1.963898e+000,0,,0,
1560551074.326,,5.000000e+003,1.003434e+002,-1.290938e-006,1.847348e-007,0.000000e+000,0.000000e+000,2,0.000000e+000,1.825000e+000,,,,,,,,,,,,,,,,,,0,4.000000e+000,1.000000e+000,3,8,1.969322e+000,0,,0,
1560551136.376,,5.000000e+003,9.823337e+001,-1.327766e-006,1.530737e-007,0.000000e+000,0.000000e+000,2,0.000000e+000,1.825000e+000,,,,,,,,,,,,,,,,,,0,4.000000e+000,1.000000e+000,3,8,1.970818e+000,0,,0,
1560551197.686,,5.000000e+003,9.621037e+001,-1.348226e-006,1.859212e-007,0.000000e+000,0.000000e+000,2,0.000000e+000,1.825000e+000,,,,,,,,,,,,,,,,,,0,4.000000e+000,1.000000e+000,3,8,1.993134e+000,0,,0,
1560551260.376,,5.000000e+003,9.411470e+001,-1.437062e-006,2.498863e-007,0.000000e+000,0.000000e+000,2,0.000000e+000,1.825000e+000,,,,,,,,,,,,,,,,,,0,4.000000e+000,1.000000e+000,3,8,1.973030e+000,0,,0,
1560551321.616,,5.000000e+003,9.205406e+001,-1.361944e-006,1.530632e-007,0.000000e+000,0.000000e+000,2,0.000000e+000,1.825000e+000,,,,,,,,,,,,,,,,,,0,4.000000e+000,1.000000e+000,3,8,1.988693e+000,0,,0,
1560551384.516,,5.000000e+003,8.995055e+001,-1.305461e-006,2.536406e-007,0.000000e+000,0.000000e+000,2,0.000000e+000,1.825000e+000,,,,,,,,,,,,,,,,,,0,4.000000e+000,1.000000e+000,3,8,2.010468e+000,0,,0,
1560551446.206,,5.000000e+003,8.781554e+001,-1.233797e-006,2.244762e-007,0.000000e+000,0.000000e+000,2,0.000000e+000,1.825000e+000,,,,,,,,,,,,,,,,,,0,4.000000e+000,1.000000e+000,3,8,2.034698e+000,0,,0,
1560551508.416,,5.000000e+003,8.569127e+001,-1.190010e-006,2.637662e-007,0.000000e+000,0.000000e+000,2,0.000000e+000,1.825000e+000,,,,,,,,,,,,,,,,,,0,4.000000e+000,1.000000e+000,3,8,2.023552e+000,0,,0,
1560551569.396,,5.000000e+003,8.356711e+001,-1.119855e-006,3.105484e-007,0.000000e+000,0.000000e+000,2,0.000000e+000,1.825000e+000,,,,,,,,,,,,,,,,,,0,4.000000e+000,1.000000e+000,3,8,2.012833e+000,0,,0,
1560551630.527,,5.000000e+003,8.142824e+001,-1.276385e-006,2.171870e-007,0.000000e+000,0.000000e+000,2,0.000000e+000,1.825000e+000,,,,,,,,,,,,,,,,,,0,4.000000e+000,1.000000e+000,3,8,2.029694e+000,0,,0,
1560551691.667,,5.000000e+003,7.931259e+001,-1.230876e-006,3.473724e-007,0.000000e+000,0.000000e+000,2,0.000000e+000,1.825000e+000,,,,,,,,,,,,,,,,,,0,4.000000e+000,1.000000e+000,3,8,1.994736e+000,0,,0,
1560551753.387,,5.000000e+003,7.718125e+001,-1.244997e-006,2.555433e-007,0.000000e+000,0.000000e+000,2,0.000000e+000,1.825000e+000,,,,,,,,,,,,,,,,,,0,4.000000e+000,1.000000e+000,3,8,2.037704e+000,0,,0,
1560551815.697,,5.000000e+003,7.504822e+001,-1.278364e-006,3.400254e-007,0.000000e+000,0.000000e+000,2,0.000000e+000,1.825000e+000,,,,,,,,,,,,,,,,,,0,4.000000e+000,1.000000e+000,3,8,2.011314e+000,0,,0,
1560551878.097,,5.000000e+003,7.294010e+001,-1.165638e-006,2.375266e-007,0.000000e+000,0.000000e+000,2,0.000000e+000,1.825000e+000,,,,,,,,,,,,,,,,,,0,4.000000e+000,1.000000e+000,3,8,2.042694e+000,0,,0,
1560551939.967,,5.000000e+003,7.080780e+001,-1.112627e-006,2.806327e-007,0.000000e+000,0.000000e+000,2,0.000000e+000,1.825000e+000,,,,,,,,,,,,,,,,,,0,4.000000e+000,1.000000e+000,3,8,2.075928e+000,0,,0,
1560552001.697,,5.000000e+003,6.865640e+001,-1.305412e-006,2.270890e-007,0.000000e+000,0.000000e+000,2,0.000000e+000,1.825000e+000,,,,,,,,,,,,,,,,,,0,4.000000e+000,1.000000e+000,3,8,2.093269e+000,0,,0,
1560552062.757,,5.000000e+003,6.646535e+001,-1.198866e-006,2.390017e-007,0.000000e+000,0.000000e+000,2,0.000000e+000,1.825000e+000,,,,,,,,,,,,,,,,,,0,4.000000e+000,1.000000e+000,3,8,2.119881e+000,0,,0,
1560552124.237,,5.000000e+003,6.423451e+001,-1.242216e-006,1.708482e-007,0.000000e+000,0.000000e+000,2,0.000000e+000,1.825000e+000,,,,,,,,,,,,,,,,,,0,4.000000e+000,1.000000e+000,3,8,2.170383e+000,0,,0,
1560552185.337,,5.000000e+003,6.199395e+001,-1.201363e-006,1.782707e-007,0.000000e+000,0.000000e+000,2,0.000000e+000,1.825000e+000,,,,,,,,,,,,,,,,,,0,4.000000e+000,1.000000e+000,3,8,2.184193e+000,0,,0,
1560552248.277,,5.000000e+003,5.972723e+001,-1.268981e-006,1.138544e-007,0.000000e+000,0.000000e+000,2,0.000000e+000,1.825000e+000,,,,,,,,,,,,,,,,,,0,4.000000e+000,1.000000e+000,3,8,2.232578e+000,0,,0,
1560552310.537,,5.000000e+003,5.745691e+001,-1.248461e-006,1.685259e-007,0.000000e+000,0.000000e+000,2,0.000000e+000,1.825000e+000,,,,,,,,,,,,,,,,,,0,4.000000e+000,1.000000e+000,3,8,2.116302e+000,0,,0,
1560552371.788,,5.000000e+003,5.524908e+001,-1.195454e-006,1.810048e-007,0.000000e+000,0.000000e+000,2,0.000000e+000,1.825000e+000,,,,,,,,,,,,,,,,,,0,4.000000e+000,1.000000e+000,3,8,2.075218e+000,0,,0,
1560552433.308,,5.000000e+003,5.299177e+001,-1.170648e-006,1.579163e-007,0.000000e+000,0.000000e+000,2,0.000000e+000,1.825000e+000,,,,,,,,,,,,,,,,,,0,4.000000e+000,1.000000e+000,3,8,2.161991e+000,0,,0,
1560552495.458,,5.000000e+003,5.074049e+001,-1.170844e-006,1.759968e-007,0.000000e+000,0.000000e+000,2,0.000000e+000,1.825000e+000,,,,,,,,,,,,,,,,,,0,4.000000e+000,1.000000e+000,3,8,2.157669e+000,0,,0,
1560552557.198,,5.000000e+003,4.844998e+001,-1.081194e-006,2.021523e-007,0.000000e+000,0.000000e+000,2,0.000000e+000,1.825000e+000,,,,,,,,,,,,,,,,,,0,4.000000e+000,1.000000e+000,3,8,2.230030e+000,0,,0,
1560552618.238,,5.000000e+003,4.614662e+001,-1.106275e-006,1.574835e-007,0.000000e+000,0.000000e+000,2,0.000000e+000,1.825000e+000,,,,,,,,,,,,,,,,,,0,4.000000e+000,1.000000e+000,3,8,2.235409e+000,0,,0,
1560552680.458,,5.000000e+003,4.380985e+001,-1.209276e-006,1.808561e-007,0.000000e+000,0.000000e+000,2,0.000000e+000,1.825000e+000,,,,,,,,,,,,,,,,,,0,4.000000e+000,1.000000e+000,3,8,2.282829e+000,0,,0,
1560552742.218,,5.000000e+003,4.147573e+001,-1.033813e-006,1.474946e-007,0.000000e+000,0.000000e+000,2,0.000000e+000,1.825000e+000,,,,,,,,,,,,,,,,,,0,4.000000e+000,1.000000e+000,3,8,2.258587e+000,0,,0,
1560552805.178,,5.000000e+003,3.914114e+001,-1.065039e-006,1.442877e-007,0.000000e+000,0.000000e+000,2,0.000000e+000,1.825000e+000,,,,,,,,,,,,,,,,,,0,4.000000e+000,1.000000e+000,3,8,2.245182e+000,0,,0,
1560552866.908,,5.000000e+003,3.679270e+001,-1.063976e-006,1.538013e-007,0.000000e+000,0.000000e+000,2,0.000000e+000,1.825000e+000,,,,,,,,,,,,,,,,,,0,4.000000e+000,1.000000e+000,3,8,2.224621e+000,0,,0,
1560552929.918,,5.000000e+003,3.450657e+001,-9.346130e-007,1.395945e-007,0.000000e+000,0.000000e+000,2,0.000000e+000,1.825000e+000,,,,,,,,,,,,,,,,,,0,4.000000e+000,1.000000e+000,3,8,2.120548e+000,0,,0,
1560552992.158,,5.000000e+003,3.240310e+001,-1.013318e-006,1.732505e-007,0.000000e+000,0.000000e+000,2,0.000000e+000,1.825000e+000,,,,,,,,,,,,,,,,,,0,4.000000e+000,1.000000e+000,3,8,2.053360e+000,0,,0,
1560553055.809,,5.000000e+003,3.019243e+001,-9.971995e-007,1.006315e-007,0.000000e+000,0.000000e+000,2,0.000000e+000,1.825000e+000,,,,,,,,,,,,,,,,,,0,4.000000e+000,1.000000e+000,3,8,2.135540e+000,0,,0,
1560553118.449,,5.000000e+003,2.799867e+001,-1.034876e-006,9.133856e-008,0.000000e+000,0.000000e+000,2,0.000000e+000,1.825000e+000,,,,,,,,,,,,,,,,,,0,4.000000e+000,1.000000e+000,3,8,2.102589e+000,0,,0,
1560553180.899,,5.000000e+003,2.578760e+001,-8.721698e-007,1.223530e-007,0.000000e+000,0.000000e+000,2,0.000000e+000,1.825000e+000,,,,,,,,,,,,,,,,,,0,4.000000e+000,1.000000e+000,3,8,2.316910e+000,0,,0,
1560553243.749,,5.000000e+003,2.339993e+001,-8.337537e-007,1.019166e-007,0.000000e+000,0.000000e+000,2,0.000000e+000,1.825000e+000,,,,,,,,,,,,,,,,,,0,4.000000e+000,1.000000e+000,3,8,1.769020e+000,0,,0,
1560553307.129,,5.000000e+003,2.140238e+001,-8.691223e-007,1.150151e-007,0.000000e+000,0.000000e+000,2,0.000000e+000,1.825000e+000,,,,,,,,,,,,,,,,,,0,4.000000e+000,1.000000e+000,3,8,2.060820e+000,0,,0,
1560553369.279,,5.000000e+003,1.927655e+001,-8.361371e-007,7.902178e-008,0.000000e+000,0.000000e+000,2,0.000000e+000,1.825000e+000,,,,,,,,,,,,,,,,,,0,4.000000e+000,1.000000e+000,3,8,1.974430e+000,0,,0,
1560553432.529,,5.000000e+003,1.713037e+001,-7.586559e-007,1.089740e-007,0.000000e+000,0.000000e+000,2,0.000000e+000,1.825000e+000,,,,,,,,,,,,,,,,,,0,4.000000e+000,1.000000e+000,3,8,2.114431e+000,0,,0,
1560553495.879,,5.000000e+003,1.497538e+001,-6.975076e-007,5.824377e-008,0.000000e+000,0.000000e+000,2,0.000000e+000,1.825000e+000,,,,,,,,,,,,,,,,,,0,4.000000e+000,1.000000e+000,3,8,2.040230e+000,0,,0,
1560553559.279,,5.000000e+003,1.279399e+001,-6.335165e-007,7.016601e-008,0.000000e+000,0.000000e+000,2,0.000000e+000,1.825000e+000,,,,,,,,,,,,,,,,,,0,4.000000e+000,1.000000e+000,3,8,2.042370e+000,0,,0,
1560553622.969,,5.000000e+003,1.064538e+001,-5.032193e-007,5.522839e-008,0.000000e+000,0.000000e+000,2,0.000000e+000,1.825000e+000,,,,,,,,,,,,,,,,,,0,4.000000e+000,1.000000e+000,3,8,2.012193e+000,0,,0,
1560553685.829,,5.000000e+003,8.642133e+000,-3.803453e-007,6.833976e-008,0.000000e+000,0.000000e+000,2,0.000000e+000,1.825000e+000,,,,,,,,,,,,,,,,,,0,4.000000e+000,1.000000e+000,3,8,1.781409e+000,0,,0,
1560553747.929,,5.000000e+003,6.905149e+000,-2.383802e-007,9.501366e-008,0.000000e+000,0.000000e+000,2,0.000000e+000,1.825000e+000,,,,,,,,,,,,,,,,,,0,4.000000e+000,1.000000e+000,3,8,1.571218e+000,0,,0,
1560553810.260,,5.000000e+003,5.093345e+000,6.369334e-008,1.211098e-007,0.000000e+000,0.000000e+000,2,0.000000e+000,1.825000e+000,,,,,,,,,,,,,,,,,,0,4.000000e+000,1.000000e+000,3,8,1.922458e+000,0,,0,
1560553995.100,,5.000000e+003,4.004786e+000,3.378653e-007,2.744483e-008,0.000000e+000,0.000000e+000,2,0.000000e+000,1.825000e+000,,,,,,,,,,,,,,,,,,0,4.000000e+000,1.000000e+000,3,8,1.258259e-001,0,,0,
1560554183.500,,5.000000e+003,3.980632e+000,3.536140e-007,3.091217e-008,0.000000e+000,0.000000e+000,2,0.000000e+000,1.825000e+000,,,,,,,,,,,,,,,,,,0,4.000000e+000,1.000000e+000,3,8,6.631112e-002,0,,0,
1560554243.940,,5.000000e+003,3.996361e+000,3.622604e-007,2.286347e-008,0.000000e+000,0.000000e+000,2,0.000000e+000,1.825000e+000,,,,,,,,,,,,,,,,,,0,4.000000e+000,1.000000e+000,3,8,6.949902e-003,0,,0,
1560554304.570,,5.000000e+003,3.999885e+000,3.695264e-007,1.620555e-008,0.000000e+000,0.000000e+000,2,0.000000e+000,1.825000e+000,,,,,,,,,,,,,,,,,,0,4.000000e+000,1.000000e+000,3,8,9.485006e-003,0,,0,
1560554364.600,,5.000000e+003,4.001419e+000,3.692196e-007,9.579994e-009,0.000000e+000,0.000000e+000,2,0.000000e+000,1.825000e+000,,,,,,,,,,,,,,,,,,0,4.000000e+000,1.000000e+000,3,8,1.122212e-002,0,,0,
1560554425.500,,5.000000e+003,4.003618e+000,3.659656e-007,7.083130e-009,0.000000e+000,0.000000e+000,2,0.000000e+000,1.825000e+000,,,,,,,,,,,,,,,,,,0,4.000000e+000,1.000000e+000,3,8,3.848553e-003,0,,0,
1560554485.240,,5.000000e+003,4.005948e+000,3.863822e-007,2.014859e-008,0.000000e+000,0.000000e+000,2,0.000000e+000,1.825000e+000,,,,,,,,,,,,,,,,,,0,4.000000e+000,1.000000e+000,3,8,2.124786e-003,0,,0,
1560554544.941,,5.000000e+003,4.007020e+000,3.667050e-007,1.416533e-008,0.000000e+000,0.000000e+000,2,0.000000e+000,1.825000e+000,,,,,,,,,,,,,,,,,,0,4.000000e+000,1.000000e+000,3,8,1.495838e-003,0,,0,